Workbook

Sheet Roteiro
B2: Conferências | E2: Medição | F2: 11/2025 | G2: 45962
A4: 1 | B4: Atualizar geração na aba "Hist.Geração" | H4: G:\Drives compartilhados\8 Geração Distribuída\15. Operação e Manutenção\2.1 Contas de Luz Usinas Solar Maranhão
A5: 2 | B5: Atualizar consumo na aba "Hist.Consumo"
A6: 3 | B6: Atualizar rateio (se houver mudança) - "Cad.Consumo - Paula
A7: 4 | B7: Atualizar banceira tarifária - "Hist BT" - google - site gov (ANEEL)
A8: 5 | B8: Paula confere as medições e saldos Acumulados (aba medições)
A9: 6 | B9: Emitir faturas na ana "Faturas" com base no número do recibo da aba medições
A10: 7
A11: 8
A12: 9
A13: 10
A14: 11
A15: 12
A16: 13
A17: 14
A18: 15

Sheet Cad.Usinas
A1: Cadastro Usinas
A3: Nome | B3: Conta Contrato | C3: Instalação | D3: Potência (kW) | E3: Geração Mês (kWh) | F3: CNPJ Titular | G3: E-mail de acesso equatorial | H3: Desconto | I3: Desconto Band. Tar. | J3: Dia de leitura | K3: Endereço (igual a conta) | L3: Razão do Titular | M3: Data de Inicio | N3: Data de Saída
A4: Usina 1 | B4: 3023633492 | D4: 75 | E4: =168000/12 -> 14000 | F4: 43.790.285/0001-14 | H4: 0.15 | I4: 0.15 | K4: RD MA 315 , S/N , TRATA SE DE UMA USINA DE GERACAO CEP: 65590-000 JATOBA - BARREIRINHAS - MA | L4: SOLAR MARANHAO ENERGIAS RENOVAVEIS LTDA
A5: Usina 2 | B5: 3023594470 | D5: 75 | E5: =168000/12 -> 14000 | F5: 45.101.934/0001-58 | H5: 0.15 | I5: 0.15 | K5: RD SAO SEBASTIAO , S/N , RODOVIA MA 315 KM 21 8 SN CEP: 65590-000 AEROPORTO NOVO - BARREIRINHAS - MA | L5: EMPRESA DE GERACAO DE ENERGIA FOTOVOLTAICA MARANHENSE 02 (EGEFOM02) SPE LTDA
A6: Usina 3 | B6: 3023637013 | D6: 75 | E6: =168000/12 -> 14000 | F6: 45.181.504/0001-93 | H6: 0.15 | I6: 0.15 | K6: PV MANGABA , S/N , RUA PROJETADA CEP: 65590-000 MANGABA - BARREIRINHAS - MA | L6: EMPRESA DE GERACAO DE ENERGIA FOTOVOLTAICA MARANHENSE 05 (EGEFOM05) SPE LTDA

Sheet Cad.RateioConsumo
B1: Cadastro Rateio Consumo
B2: 1 | C2: 2 | D2: 3 | E2: 4 | F2: 5 | G2: 6 | H2: 7 | I2: 8 | J2: 9 | K2: 10 | L2: 11 | M2: 12 | N2: 13 | O2: 14 | U2: 20
B3: ID | C3: Nome | D3: # | E3: CNPJ/CPF | F3: Conta Contrato | G3: Tipo Instalação | H3: Consumo Médio (kWh) | I3: Desconto | J3: Desconto Band. Tar. | K3: Usina Associada | L3: Percentual Rateio (%) | M3: Acesso equatorial | N3: Endereço (igual a conta) | O3: Razão do Titular | P3: Data de Inicio | Q3: Vigente | S3: Whatsaap de Cobrança | T3: E-mail Cobrança | U3: Data de Nascimento | Z3: 2056
A4: =B4&Q4 -> 3.1sim | B4: 3.1 | C4: Associação dos Moradores do Residencial Araçagy | D4: 14 | E4: 20.069.500/0001-97 | F4: 3021142432 | G4: Comercial | H4: 205.36364 | I4: 0.15 | J4: 0.15 | K4: Usina 3 | L4: =ROUND(1.46688311688312%,4) -> 0.0147 | M4: financeiro@amelsolar.com.br | N4: R. da Agranja , 50 , CP 26 CS 59 PS 1, CEP: 65138-000 Aracagi - Raposa - MA | O4: Associação dos Moradores do Residencial Araçagy | P4: 45897 | Q4: =IF(P4<Roteiro!$G$2,"sim","não") -> sim | Z4: 2196
A5: =B5&Q5 -> 3.2sim | B5: 3.2 | C5: Associação dos Moradores do Residencial Araçagy | D5: 14 | E5: 20.069.500/0001-97 | F5: 3021149593 | G5: Comercial | H5: 734.33333 | I5: 0.15 | J5: 0.15 | K5: Usina 3 | L5: =ROUND(5.2452380952381%,4) -> 0.0525 | M5: financeiro@amelsolar.com.br | N5: R. da Agranja , 50 , CP 26 CS 36 PS 4, cep: 65138-000 Aracagi - Raposa - MA | O5: Associação dos Moradores do Residencial Araçagy | P5: 45897 | Q5: =IF(P5<Roteiro!$G$2,"sim","não") -> sim | Z5: 2391
A6: =B6&Q6 -> 3.3sim | B6: 3.3 | C6: Associação dos Moradores do Residencial Araçagy | D6: 14 | E6: 20.069.500/0001-97 | F6: 3021150559 | G6: Comercial | H6: 2086.4545 | I6: 0.15 | J6: 0.15 | K6: Usina 3 | L6: 0.107 | M6: financeiro@amelsolar.com.br | N6: R. Granja , s/n , CP 26 CS 36 PS 1, cep: 65138-000 Aracagi - Raposa - MA, | O6: Associação dos Moradores do Residencial Araçagy | P6: 45897 | Q6: =IF(P6<Roteiro!$G$2,"sim","não") -> sim | S6: suporteigsgestao@gmail.com | T6: claudemirgeo@icloud.com | V6: 1500 | W6: =ROUND(10.71%,4) -> 0.1071 | X6: alteração não implementada | AA6: 4825
A7: =B7&Q7 -> 3.4sim | B7: 3.4 | C7: Antonio Jose Souza Filho | D7: 10 | E7: 682.957.583-49 | F7: 3007625048 | G7: Residencial | H7: 417.15385 | I7: 0.15 | J7: 0.15 | K7: Usina 3 | L7: =ROUND(2.97967032967033%,4) -> 0.0298 | M7: =U7 -> 28283 | N7: R. 03 , 23 , LOT ALTO DO JAGUAREMA QD 05 LOT - ALTO DO JAGUAREMA QD 05 CEP: 65110-000 ARACAGY | O7: =C7 -> Antonio Jose Souza Filho | P7: 45897 | Q7: =IF(P7<Roteiro!$G$2,"sim","não") -> sim | U7: 28283 | Z7: 2436
A8: =B8&Q8 -> 3.5sim | B8: 3.5 | C8: João Carlos Pereira Dutra Filho | D8: 11 | E8: 064837473-49 | F8: 1163310 | G8: Residencial | H8: 848.69231 | I8: 0.15 | J8: 0.15 | K8: Usina 3 | L8: =ROUND(6.06208791208791%,4) -> 0.0606 | M8: =U8 -> 19543 | N8: R. 13 , 31 , QD 7 QD 7 CEP: 65010-000 PLN - VINHAIS II - SAO LUIS - MA | O8: =C8 -> João Carlos Pereira Dutra Filho | P8: 45961 | Q8: =IF(P8<Roteiro!$G$2,"sim","não") -> sim | U8: 19543 | V8: / | Z8: 2376
A9: =B9&Q9 -> 3.6sim | B9: 3.6 | C9: Patricia Maria Abreu Machado | D9: 19 | E9: 676.211.553-53 | F9: 3006793931 | G9: Residencial | H9: 776.76923 | I9: 0.15 | J9: 0.15 | K9: Usina 3 | L9: =ROUND(5.54835164835165%,4) -> 0.0555 | M9: =U9 -> 27174 | N9: R. MARIA F REIS , 20 , QD B CONJ BASA QD B CONJ BASA CEP: 65010-000 SAO FRANCISCO, na cidade de São Luís, Estado do Maranhão | O9: =C9 -> Patricia Maria Abreu Machado | P9: 45961 | Q9: =IF(P9<Roteiro!$G$2,"sim","não") -> sim | U9: 27174 | V9: / | Z9: 1933
A10: =B10&Q10 -> 3.7sim | B10: 3.7 | C10: Fatima Abdel Hafiz Khalifa Cavalcanti | D10: 15 | E10: 840.670.553-15 | F10: 38398091 | G10: Residencial | H10: 1013.3846 | I10: 0.15 | J10: 0.15 | K10: Usina 3 | L10: =ROUND(7.23846153846154%,4) -> 0.0724 | M10: =U10 -> 29085 | N10: Rua Nova nº63, Anil, São Luis, MA CEP: 65046-160 | O10: =C10 -> Fatima Abdel Hafiz Khalifa Cavalcanti | P10: 45961 | Q10: =IF(P10<Roteiro!$G$2,"sim","não") -> sim | S10: 98 8124-7136 | U10: 29085
A11: =B11&Q11 -> 3.8não | B11: 3.8 | C11: Ana Maria Marques De Brito | D11: 31 | E11: 920.517.663-04 | F11: 3020257082 | G11: Residencial | H11: 1193 | I11: 0.15 | J11: 0.15 | K11: Usina 3 | L11: 0.0852 | M11: =U11 -> 29585 | N11: R. F , 20 , QD 5 QD 5 CEP: 65010-000 PQ ATENAS - SAO LUIS - MA | O11: =C11 -> Ana Maria Marques De Brito | P11: 46023 | Q11: =IF(P11<Roteiro!$G$2,"sim","não") -> não | S11: 98 8124-7136 | U11: 29585
A12: =B12&Q12 -> 3.0sim | B12: 3.0 | C12: Usina 3 | D12: PJ | E12: 61.434.675/0001-33 | F12: 3023637013 | H12: =14000-SUM(H4:H9) -> 8931.2331 | I12: 0.15 | J12: 0.15 | K12: Usina 3 | L12: =100%-SUM(L4:L9) -> 0.6799 | M12: financeiro@amelsolar.com.br | N12: =Cad.Usinas!K6 -> PV MANGABA , S/N , RUA PROJETADA CEP: 65590-000 MANGABA - BARREIRINHAS - MA | O12: =C12 -> Usina 3 | P12: 45839 | Q12: =IF(P12<Roteiro!$G$2,"sim","não") -> sim | V12: 45870 | W12: 700 | Z12: 1922
A13: =B13&Q13 | V13: 45901 | W13: =H6-Z21 -> 321.45455 | X13: =W12+W13 -> 1021.4545 | Z13: 1902
A14: =B14&Q14 -> 2.1sim | B14: 2.1 | C14: Lucas Medeiros Lima | D14: PJ | E14: 612.634.903-28 | F14: 3002796782 | G14: Residencial | H14: 1536.5 | I14: 0.15 | J14: 0.15 | K14: Usina 2 | L14: =ROUND(10.975%,4) -> 0.1098 | M14: =U14 -> 35943 | N14: VL ARISTOTELES , S/N , RUA FRANCISCO MARCELINO DE MEDEIROS RUA FRANCISCO MARCELINO DE MEDEIROS CEP: 65728-000 CENTRO - LIMA CAMPOS - MA | O14: =C14 -> Lucas Medeiros Lima | P14: 45961 | Q14: =IF(P14<Roteiro!$G$2,"sim","não") -> sim | S14: (99) 8262-4178 | U14: 35943 | V14: 45931 | W14: =-$Z$21+$V$6 -> -265 | X14: =X10+W14 -> -265 | Z14: 2060
A15: =B15&Q15 -> 2.2sim | B15: 2.2 | C15: SORRISO SAUDE ODONTOLOGIA LTDA | D15: PJ | E15: 60.080.581/0001-40 | F15: 3022893768 | G15: Comercial | H15: 859 | I15: 0.17 | J15: 0.17 | K15: Usina 2 | L15: =ROUND(6.13571428571429%,4) -> 0.0614 | M15: financeiro@amelsolar.com.br | N15: AV RAIMUNDO CORREIA DA SILVA , 1346 , B B CEP: 65633-641 CIDADE NOVA - TIMON - MA | O15: =C15 -> SORRISO SAUDE ODONTOLOGIA LTDA | P15: 45961 | Q15: =IF(P15<Roteiro!$G$2,"sim","não") -> sim | S15: +55 86 8824-9275 | V15: 45931 | W15: =-$Z$21+$V$6 -> -265 | X15: =X12+W15 -> -265 | Z15: 2060
A16: =B16&Q16 -> 2.3não | B16: 2.3 | C16: José de Ribamar Aguiar Costa (Zeca) | D16: PF | E16: 225.692.943-49 | F16: 3005806061 | G16: Residencial | H16: 172.38462 | I16: 0.15 | J16: 0.15 | K16: Usina 2 | L16: 0.0123 | M16: =U16 -> 24298 | N16: R. PRINCIPAL , 10 , CEP: 65590-000 BOA VISTA - BARREIRINHAS - MA | O16: =C16 -> José de Ribamar Aguiar Costa (Zeca) | P16: 46023 | Q16: =IF(P16<Roteiro!$G$2,"sim","não") -> não | S16: +55 86 8824-9275 | U16: 24298 | V16: 45931 | W16: =-$Z$21+$V$6 -> -265 | X16: =X13+W16 -> 756.45455 | Z16: 2060
B17: 2.4 | C17: Fernando Fonseca Diniz (Andre TVN) | D17: PF | E17: 011.087.293-20 | F17: 3022544461 | G17: Residencial | H17: 241.125 | I17: 0.15 | J17: 0.15 | K17: Usina 2 | L17: 0.017223214 | M17: =U17 -> 31103 | N17: AL E , 801 , APT TORRE DA MANHA BRISAS LIFE APT TORRE DA MANHA BRISAS LIFE CEP: 65070-628 ALTO DO CALHAU - SAO LUIS - MA | U17: 31103
A18: =B18&Q22 -> 2.0 | B18: 2.0 | C18: Usina 2 | D18: PJ | E18: 61.434.675/0001-33 | F18: 3023594470 | G18: Comercial | H18: =14000 -> 14000 | I18: 0.15 | J18: 0.15 | K18: Usina 2 | L18: =100% -> 1 | M18: financeiro@amelsolar.com.br | N18: RD SAO SEBASTIAO , S/N , RODOVIA MA 315 KM 21 8 SN CEP: 65590-000 AEROPORTO NOVO - BARREIRINHAS - MA | O18: =C18 -> Usina 2 | P18: 45839 | Q18: =IF(P18<Roteiro!$G$2,"sim","não") -> sim | V18: 45931 | W18: =-$Z$21+$V$6 -> -265 | X18: =X13+W18 -> 756.45455 | Z18: 2060
A19: =B19&Q19 | V19: 45962 | W19: =W18 -> -265 | X19: =X18+W19 -> 491.45455 | Z19: 1671
A20: =B20&Q20 -> 1.0sim | B20: 1.0 | C20: Usina 1 | D20: PJ | E20: 61.434.675/0001-33 | F20: 3023633492 | H20: =14000 -> 14000 | I20: 0.15 | J20: 0.15 | K20: Usina 1 | L20: =100%-SUM(L12:L13) -> 0.3201 | M20: financeiro@amelsolar.com.br | O20: =C20 -> Usina 1 | P20: 45839 | Q20: =IF(P20<Roteiro!$G$2,"sim","não") -> sim | V20: 45992 | W20: =W19 -> -265 | X20: =X19+W20 -> 226.45455 | Z20: 2008
V21: 46023 | W21: =W20 -> -265 | X21: =X20+W21 -> -38.545455 | Z21: 1765
V23: 46082 | Z23: 700
Z24: =P26-Z23 -> 1736
C26: Hitórico Medições | O26: Max | P26: =MAX(Z3:Z21) -> 2436
C27: 45992 | E27: =SUMIF(Medições!K:K,Cad.RateioConsumo!C27,Medições!V:V) -> 7867.43 | O27: Média | P27: =AVERAGE(Z3:Z21) -> 2059.7333
C28: 45962 | E28: =SUMIF(Medições!K:K,Cad.RateioConsumo!C28,Medições!V:V) -> 4128.56
C29: 45931 | E29: =SUMIF(Medições!K:K,Cad.RateioConsumo!C29,Medições!V:V) -> 3478.63
C30: 45901 | E30: =SUMIF(Medições!K:K,Cad.RateioConsumo!C30,Medições!V:V) -> 3005.25
C31: 45870 | E31: =SUMIF(Medições!K:K,Cad.RateioConsumo!C31,Medições!V:V) -> 0
E32: =SUMIF(Medições!K:K,Cad.RateioConsumo!C32,Medições!V:V) -> 0

Sheet Hist.Geração
J1: G:\Drives compartilhados\8 Geração Distribuída\15. Operação e Manutenção\2.1 Contas de Luz Usinas Solar Maranhão
B2: Histórico Geração Usinas
B4: Nome | C4: Conta Contrato | D4: Medição | E4: Leitura | F4: Referência
A5: =B5&F5 -> Usina 107/2025 | B5: Usina 1 | C5: 3023633492 | D5: 12608 | E5: 45863 | F5: 07/2025
A6: =B6&F6 -> Usina 108/2025 | B6: Usina 1 | C6: 3023633492 | D6: 16597 | E6: 45895 | F6: 08/2025
A7: =B7&F7 -> Usina 109/2025 | B7: Usina 1 | C7: 3023633492 | D7: 16887 | E7: 45926 | F7: 09/2025
A8: =B8&F8 -> Usina 110/2025 | B8: Usina 1 | C8: 3023633492 | D8: 16135 | E8: 45957 | F8: 10/2025
A9: =B9&F9 -> Usina 111/2025 | B9: Usina 1 | C9: 3023633492 | D9: 15452 | E9: 45987 | F9: 11/2025
A10: =B10&F10 -> Usina 112/2025 | B10: Usina 1 | C10: 3023633492 | D10: 12122 | E10: 27/12/2025 | F10: 12/2025
A11: =B11&F11 -> Usina 101/2026 | B11: Usina 1 | C11: 3023633492 | D11: 11655 | E11: 46049 | F11: 01/2026
A12: =B12&F12
A13: =B13&F13 -> Usina 207/2025 | B13: Usina 2 | C13: 3023594470 | D13: 15120 | E13: 45863 | F13: 07/2025
A14: =B14&F14 -> Usina 208/2025 | B14: Usina 2 | C14: 3023594470 | D14: 16448 | E14: 45895 | F14: 08/2025
A15: =B15&F15 -> Usina 209/2025 | B15: Usina 2 | C15: 3023594470 | D15: 16732 | E15: 45926 | F15: 09/2025
A16: =B16&F16 -> Usina 210/2025 | B16: Usina 2 | C16: 3023594470 | D16: 16983 | E16: 45957 | F16: 10/2025
A17: =B17&F17 -> Usina 211/2025 | B17: Usina 2 | C17: 3023594470 | D17: 15839 | E17: 45987 | F17: 11/2025
A18: =B18&F18 -> Usina 212/2025 | B18: Usina 2 | C18: 3023594470 | D18: 13792 | E18: 46018 | F18: 12/2025
A19: =B19&F19 -> Usina 201/2026 | B19: Usina 2 | C19: 3023594470 | D19: 13974 | E19: 46049 | F19: 01/2026
A20: =B20&F20
A21: =B21&F21 -> Usina 307/2025 | B21: Usina 3 | C21: 3023637013 | D21: 12794 | E21: 45867 | F21: 07/2025
A22: =B22&F22 -> Usina 308/2025 | B22: Usina 3 | C22: 3023637013 | D22: 16329 | E22: 45898 | F22: 08/2025
A23: =B23&F23 -> Usina 309/2025 | B23: Usina 3 | C23: 3023637013 | D23: 16338 | E23: 45929 | F23: 09/2025
A24: =B24&F24 -> Usina 310/2025 | B24: Usina 3 | C24: 3023637013 | D24: 17371 | E24: 45959 | F24: 10/2025
A25: =B25&F25 -> Usina 311/2025 | B25: Usina 3 | C25: 3023637013 | D25: 15708 | E25: 45989 | F25: 11/2025
A26: =B26&F26 -> Usina 312/2025 | B26: Usina 3 | C26: 3023637013 | D26: 14276 | E26: 46021 | F26: 12/2025
A27: =B27&F27 -> Usina 301/2026 | B27: Usina 3 | C27: 3023637013 | D27: 13888 | E27: 46051 | F27: 01/2026

Sheet Hist.Consum
B1: 1 | C1: 2 | D1: 3 | E1: 4 | F1: 5 | G1: 6 | H1: 7 | I1: 8 | J1: 9 | K1: 10 | L1: 11 | M1: 12 | N1: 13 | O1: 14 | P1: 15 | Q1: 16 | R1: 17 | S1: 18 | T1: 19 | U1: 20 | V1: 21 | W1: 22 | X1: 23 | Y1: 24 | Z1: 12
C2: Histórico Consumo
M3: Consumo | P3: Dev Geração | S3: Bandeira | T3: Tributos (Aliquota | X3: Adicionais | Y3: Observação
C4: Nome | D4: Conta Contrato | E4: Nome | F4: Consumidores | G4: Conta Contrato | H4: Consumo Médio | I4: Percentual Rateio (%) | J4: Referência | K4: Leitura | L4: Vencimento | M4: Quantidade | N4: Tarifa | O4: Valor R$ | P4: Quantidade | Q4: Tarifa | R4: Valor R$ | S4: Valor R$ | T4: ICMS | U4: Pis | V4: Cofins | W4: Tarifa Vigente | X4: Total Combrança adicional GD2 | Z4: SaldoAcumulado Geração | AB4: CPF | AC4: Data Nascimento
A6: ok | B6: =E6&J6 -> 3.102/2026 | C6: Usina 3 | D6: =VLOOKUP(C6,Cad.Usinas!$A$4:$B$6,2,FALSE) -> 3023637013 | E6: 3.1 | F6: =VLOOKUP(E6,Cad.RateioConsumo!$B$4:$Q$77,2,FALSE) -> Associação dos Moradores do Residencial Araçagy | G6: =VLOOKUP(E6,Cad.RateioConsumo!$B$4:$Q$9,5,FALSE) -> 3021142432 | H6: =VLOOKUP(E6,Cad.RateioConsumo!$B$4:$Q$9,7,FALSE) -> 205.36364 | I6: =VLOOKUP(E6,Cad.RateioConsumo!$B$4:$Q$9,11,FALSE) -> 0.0147 | J6: 02/2026 | K6: 46057 | L6: 46077 | M6: 100 | N6: 1.1284 | O6: =M6*N6 -> 112.84 | P6: 108.87 | Q6: =N6 -> 1.1284 | R6: =P6*Q6 -> 122.84891 | T6: 0.23 | U6: 0.005288 | V6: 0.02441 | W6: =ROUND(0.84318/((1-U6-V6)*(1-T6)),4) -> 1.1286 | Z6: 366.56 | AB6: =VLOOKUP(E6,Cad.RateioConsumo!$B$4:$Q$9,4,FALSE) -> 20.069.500/0001-97 | AC6: =VLOOKUP(E6,Cad.RateioConsumo!$B$4:$U$9,20,FALSE) -> 0
A7: ok | B7: =E7&J7 -> 3.202/2026 | C7: Usina 3 | D7: =VLOOKUP(C7,Cad.Usinas!$A$4:$B$6,2,FALSE) -> 3023637013 | E7: 3.2 | F7: =VLOOKUP(E7,Cad.RateioConsumo!$B$4:$Q$77,2,FALSE) -> Associação dos Moradores do Residencial Araçagy | G7: =VLOOKUP(E7,Cad.RateioConsumo!$B$4:$Q$9,5,FALSE) -> 3021149593 | H7: =VLOOKUP(E7,Cad.RateioConsumo!$B$4:$Q$9,7,FALSE) -> 734.33333 | I7: =VLOOKUP(E7,Cad.RateioConsumo!$B$4:$Q$9,11,FALSE) -> 0.0525 | J7: 02/2026 | K7: 46057 | L7: 46077 | M7: 219.41 | N7: 1.128572 | O7: =M7*N7 -> 247.61998 | P7: 818.35 | Q7: =N7 -> 1.128572 | R7: =P7*Q7 -> 923.5669 | T7: 0.23 | U7: 0.005288 | V7: 0.02441 | W7: =ROUND(0.84318/ROUND(((1-U7-V7)*(1-T7)),4),4) -> 1.1286 | AB7: =VLOOKUP(E7,Cad.RateioConsumo!$B$4:$Q$9,4,FALSE) -> 20.069.500/0001-97 | AC7: =VLOOKUP(E7,Cad.RateioConsumo!$B$4:$U$9,20,FALSE) -> 0
A8: ok | B8: =E8&J8 -> 3.302/2026 | C8: Usina 3 | D8: =VLOOKUP(C8,Cad.Usinas!$A$4:$B$6,2,FALSE) -> 3023637013 | E8: 3.3 | F8: =VLOOKUP(E8,Cad.RateioConsumo!$B$4:$Q$77,2,FALSE) -> Associação dos Moradores do Residencial Araçagy | G8: =VLOOKUP(E8,Cad.RateioConsumo!$B$4:$Q$9,5,FALSE) -> 3021150559 | H8: =VLOOKUP(E8,Cad.RateioConsumo!$B$4:$Q$9,7,FALSE) -> 2086.4545 | I8: =VLOOKUP(E8,Cad.RateioConsumo!$B$4:$Q$9,11,FALSE) -> 0.107 | J8: 02/2026 | K8: 46057 | L8: 46077 | M8: 309.27 | N8: 1.128311 | O8: =M8*N8 -> 348.95274 | P8: 1487.4 | Q8: =N8 -> 1.128311 | R8: =P8*Q8 -> 1678.2498 | T8: 0.23 | U8: 0.005288 | V8: 0.02441 | W8: =ROUND(0.84318/((1-U8-V8)*(1-T8)),4) -> 1.1286 | AB8: =VLOOKUP(E8,Cad.RateioConsumo!$B$4:$Q$9,4,FALSE) -> 20.069.500/0001-97 | AC8: =VLOOKUP(E8,Cad.RateioConsumo!$B$4:$U$9,20,FALSE) -> 0
A9: ok | B9: =E9&J9 -> 3.402/2026 | C9: Usina 3 | D9: =VLOOKUP(C9,Cad.Usinas!$A$4:$B$6,2,FALSE) -> 3023637013 | E9: 3.4 | F9: =VLOOKUP(E9,Cad.RateioConsumo!$B$4:$Q$77,2,FALSE) -> Antonio Jose Souza Filho | G9: =VLOOKUP(E9,Cad.RateioConsumo!$B$4:$Q$9,5,FALSE) -> 3007625048 | H9: =VLOOKUP(E9,Cad.RateioConsumo!$B$4:$Q$9,7,FALSE) -> 417.15385 | I9: =VLOOKUP(E9,Cad.RateioConsumo!$B$4:$Q$9,11,FALSE) -> 0.0298 | J9: 02/2026 | K9: 46058 | L9: 46077 | M9: 79.13 | N9: 1.128396 | O9: =M9*N9 -> 89.289975 | P9: 413.86 | Q9: =N9 -> 1.128396 | R9: =P9*Q9 -> 466.99797 | T9: 0.23 | U9: 0.005288 | V9: 0.02441 | W9: =ROUND(0.84318/((1-U9-V9)*(1-T9)),4) -> 1.1286 | AB9: =VLOOKUP(E9,Cad.RateioConsumo!$B$4:$Q$9,4,FALSE) -> 682.957.583-49 | AC9: =VLOOKUP(E9,Cad.RateioConsumo!$B$4:$U$9,20,FALSE) -> 28283
A10: ok | B10: =E10&J10 -> 3.501/2026 | C10: Usina 3 | D10: =VLOOKUP(C10,Cad.Usinas!$A$4:$B$6,2,FALSE) -> 3023637013 | E10: 3.5 | F10: =VLOOKUP(E10,Cad.RateioConsumo!$B$4:$Q$77,2,FALSE) -> João Carlos Pereira Dutra Filho | G10: =VLOOKUP(E10,Cad.RateioConsumo!$B$4:$Q$9,5,FALSE) -> 1163310 | H10: =VLOOKUP(E10,Cad.RateioConsumo!$B$4:$Q$9,7,FALSE) -> 848.69231 | I10: =VLOOKUP(E10,Cad.RateioConsumo!$B$4:$Q$9,11,FALSE) -> 0.0606 | J10: 01/2026 | K10: 46051 | L10: 46059 | M10: 30 | N10: 1.127667 | O10: =M10*N10 -> 33.83001 | P10: 937 | Q10: =N10 -> 1.127667 | R10: =P10*Q10 -> 1056.624 | T10: 0.23 | U10: 0.005288 | V10: 0.02441 | W10: =ROUND(0.84318/((1-U10-V10)*(1-T10)),4) -> 1.1286 | Z10: 16.03 | AB10: =VLOOKUP(E10,Cad.RateioConsumo!$B$4:$Q$9,4,FALSE) -> 064837473-49 | AC10: =VLOOKUP(E10,Cad.RateioConsumo!$B$4:$U$9,20,FALSE) -> 19543
A11: ok | B11: =E11&J11 -> 3.601/2026 | C11: Usina 3 | D11: =VLOOKUP(C11,Cad.Usinas!$A$4:$B$6,2,FALSE) -> 3023637013 | E11: 3.6 | F11: =VLOOKUP(E11,Cad.RateioConsumo!$B$4:$Q$77,2,FALSE) -> Patricia Maria Abreu Machado | G11: =VLOOKUP(E11,Cad.RateioConsumo!$B$4:$Q$9,5,FALSE) -> 3006793931 | H11: =VLOOKUP(E11,Cad.RateioConsumo!$B$4:$Q$9,7,FALSE) -> 776.76923 | I11: =VLOOKUP(E11,Cad.RateioConsumo!$B$4:$Q$9,11,FALSE) -> 0.0555 | J11: 01/2026 | K11: 46050 | L11: 46057 | M11: 100 | N11: 1.1282 | O11: =M11*N11 -> 112.82 | P11: 713 | Q11: =N11 -> 1.1282 | R11: =P11*Q11 -> 804.4066 | T11: 0.23 | U11: 0.005288 | V11: 0.02441 | W11: =ROUND(0.84318/((1-U11-V11)*(1-T11)),4) -> 1.1286 | Y11: =W11-N11 -> 0.0004 | AB11: =VLOOKUP(E11,Cad.RateioConsumo!$B$4:$Q$9,4,FALSE) -> 676.211.553-53 | AC11: =VLOOKUP(E11,Cad.RateioConsumo!$B$4:$U$9,20,FALSE) -> 27174
A12: ok | B12: =E12&J12 -> 3.701/2026 | C12: Usina 3 | D12: =VLOOKUP(C12,Cad.Usinas!$A$4:$B$6,2,FALSE) -> 3023637013 | E12: 3.7 | F12: =VLOOKUP(E12,Cad.RateioConsumo!$B$4:$Q$77,2,FALSE) -> Fatima Abdel Hafiz Khalifa Cavalcanti | G12: =VLOOKUP(E12,Cad.RateioConsumo!$B$4:$Q$22,5,FALSE) -> 38398091 | H12: =VLOOKUP(E12,Cad.RateioConsumo!$B$4:$Q$22,7,FALSE) -> 1013.3846 | I12: =VLOOKUP(E12,Cad.RateioConsumo!$B$4:$Q$22,11,FALSE) -> 0.0724 | J12: 01/2026 | K12: 46042 | L12: 46059 | M12: 169.15 | N12: 1.128348 | O12: =M12*N12 -> 190.86006 | P12: 1074.84 | Q12: =N12 -> 1.128348 | R12: =P12*Q12 -> 1212.7936 | T12: 0.23 | U12: 0.005263 | V12: 0.024274 | W12: =ROUND(0.84318/((1-U12-V12)*(1-T12)),4) -> 1.1284 | X12: =W12-Q12 -> 5.2e-05 | AB12: =VLOOKUP(E12,Cad.RateioConsumo!$B$4:$Q$19,4,FALSE) -> 840.670.553-15 | AC12: =VLOOKUP(E12,Cad.RateioConsumo!$B$4:$U$19,20,FALSE) -> 29085
A13: ok | B13: =E13&J13 -> 3.801/2026 | C13: Usina 3 | D13: =VLOOKUP(C13,Cad.Usinas!$A$4:$B$6,2,FALSE) -> 3023637013 | E13: 3.8 | F13: =VLOOKUP(E13,Cad.RateioConsumo!$B$4:$Q$77,2,FALSE) -> Ana Maria Marques De Brito | G13: =VLOOKUP(E13,Cad.RateioConsumo!$B$4:$Q$22,5,FALSE) -> 3020257082 | H13: =VLOOKUP(E13,Cad.RateioConsumo!$B$4:$Q$22,7,FALSE) -> 1193 | I13: =VLOOKUP(E13,Cad.RateioConsumo!$B$4:$Q$22,11,FALSE) -> 0.0852 | J13: 01/2026 | K13: 46051 | L13: 46064 | M13: 1225 | N13: 1.128343 | O13: =M13*N13 -> 1382.2202 | P13: 0 | Q13: =N13 -> 1.128343 | R13: =P13*Q13 -> 0 | T13: 0.23 | U13: 0.005263 | V13: 0.024274 | W13: =ROUND(0.84318/((1-U13-V13)*(1-T13)),4) -> 1.1284 | X13: =W13-Q13 -> 5.7e-05 | AB13: =VLOOKUP(E13,Cad.RateioConsumo!$B$4:$Q$19,4,FALSE) -> 920.517.663-04 | AC13: =VLOOKUP(E13,Cad.RateioConsumo!$B$4:$U$19,20,FALSE) -> 29585
B14: =E14&J14 -> 3.002/2026 | C14: Usina 3 | D14: =VLOOKUP(C14,Cad.Usinas!$A$4:$B$6,2,FALSE) -> 3023637013 | E14: 3.0 | F14: =VLOOKUP(E14,Cad.RateioConsumo!$B$4:$Q$77,2,FALSE) -> Usina 3 | G14: =VLOOKUP(E14,Cad.RateioConsumo!$B$4:$Q$77,5,FALSE) -> 3023637013 | H14: =VLOOKUP(E14,Cad.RateioConsumo!$B$4:$Q$77,7,FALSE) -> 8931.2331 | I14: =VLOOKUP(E14,Cad.RateioConsumo!$B$4:$Q$77,11,FALSE) -> 0.6799 | J14: 02/2026 | O14: =M14*N14 -> 0 | Q14: =N14 -> 0 | R14: =P14*Q14 -> 0 | W14: =ROUND(0.84318/((1-U14-V14)*(1-T14)),4) -> 0.8432 | AB14: =VLOOKUP(E14,Cad.RateioConsumo!$B$4:$Q$19,4,FALSE) -> 61.434.675/0001-33 | AC14: =VLOOKUP(E14,Cad.RateioConsumo!$B$4:$U$19,20,FALSE) -> 0
B15: =E15&J15 -> 1.002/2026 | C15: Usina 1 | D15: =VLOOKUP(C15,Cad.Usinas!$A$4:$B$6,2,FALSE) -> 3023633492 | E15: 1.0 | F15: =VLOOKUP(E15,Cad.RateioConsumo!$B$4:$Q$77,2,FALSE) -> Usina 1 | G15: =VLOOKUP(E15,Cad.RateioConsumo!$B$4:$Q$77,5,FALSE) -> 3023633492 | H15: =VLOOKUP(E15,Cad.RateioConsumo!$B$4:$Q$77,7,FALSE) -> 14000 | I15: =VLOOKUP(E15,Cad.RateioConsumo!$B$4:$Q$77,11,FALSE) -> 0.3201 | J15: 02/2026 | O15: =M15*N15 -> 0 | Q15: =N15 -> 0 | R15: =P15*Q15 -> 0 | W15: =ROUND(0.84318/((1-U15-V15)*(1-T15)),4) -> 0.8432 | AB15: =VLOOKUP(E15,Cad.RateioConsumo!$B$4:$Q$19,4,FALSE) -> #N/A | AC15: =VLOOKUP(E15,Cad.RateioConsumo!$B$4:$U$19,20,FALSE) -> #N/A
B16: =E16&J16 -> 2.102/2026 | C16: Usina 2 | D16: =VLOOKUP(C16,Cad.Usinas!$A$4:$B$6,2,FALSE) -> 3023594470 | E16: 2.1 | F16: =VLOOKUP(E16,Cad.RateioConsumo!$B$4:$Q$77,2,FALSE) -> Lucas Medeiros Lima | G16: =VLOOKUP(E16,Cad.RateioConsumo!$B$4:$Q$77,5,FALSE) -> 3002796782 | H16: =VLOOKUP(E16,Cad.RateioConsumo!$B$4:$Q$77,7,FALSE) -> 1536.5 | I16: =VLOOKUP(E16,Cad.RateioConsumo!$B$4:$Q$77,11,FALSE) -> 0.1098 | J16: 02/2026 | M16: 80 | O16: =M16*N16 -> 0 | P16: 499 | Q16: =N16 -> 0 | R16: =P16*Q16 -> 0 | W16: =ROUND(0.84318/((1-U16-V16)*(1-T16)),4) -> 0.8432 | X16: =108.62+211.48+79.91-164.51-59.72 -> 175.78 | Y16: A Equatorial errou no faturamento e cobrou indevidamente uma tarifa adicional:1)Benefício Tarifário Bruto SCEE e 2) (-) Benefício Tarifário Líquido SCEE . O saldo deste valor foi dado como desconto para não te afetar os 15% de desconto na conta até que a Equatorial reverter esse valor. | AB16: =VLOOKUP(E16,Cad.RateioConsumo!$B$4:$Q$19,4,FALSE) -> 612.634.903-28 | AC16: =VLOOKUP(E16,Cad.RateioConsumo!$B$4:$U$19,20,FALSE) -> 35943
B17: =E17&J17 -> 2.201/2026 | C17: Usina 2 | D17: =VLOOKUP(C17,Cad.Usinas!$A$4:$B$6,2,FALSE) -> 3023594470 | E17: 2.2 | F17: =VLOOKUP(E17,Cad.RateioConsumo!$B$4:$Q$77,2,FALSE) -> SORRISO SAUDE ODONTOLOGIA LTDA | G17: =VLOOKUP(E17,Cad.RateioConsumo!$B$4:$Q$77,5,FALSE) -> 3022893768 | H17: =VLOOKUP(E17,Cad.RateioConsumo!$B$4:$Q$77,7,FALSE) -> 859 | I17: =VLOOKUP(E17,Cad.RateioConsumo!$B$4:$Q$77,11,FALSE) -> 0.0614 | J17: 01/2026 | M17: 100 | N17: 1.1282 | O17: =M17*N17 -> 112.82 | P17: 399 | Q17: =N17 -> 1.1282 | R17: =P17*Q17 -> 450.1518 | S17: 1.85 | T17: 0.23 | U17: 0.005263 | V17: 0.024274 | W17: =ROUND(0.84318/((1-U17-V17)*(1-T17)),4) -> 1.1284 | AB17: =VLOOKUP(E17,Cad.RateioConsumo!$B$4:$Q$19,4,FALSE) -> 60.080.581/0001-40 | AC17: =VLOOKUP(E17,Cad.RateioConsumo!$B$4:$U$19,20,FALSE) -> 0
A18: ok | B18: =E18&J18 -> 2.301/2026 | C18: Usina 2 | D18: =VLOOKUP(C18,Cad.Usinas!$A$4:$B$6,2,FALSE) -> 3023594470 | E18: 2.3 | F18: =VLOOKUP(E18,Cad.RateioConsumo!$B$4:$Q$77,2,FALSE) -> José de Ribamar Aguiar Costa (Zeca) | G18: =VLOOKUP(E18,Cad.RateioConsumo!$B$4:$Q$77,5,FALSE) -> 3005806061 | H18: =VLOOKUP(E18,Cad.RateioConsumo!$B$4:$Q$77,7,FALSE) -> 172.38462 | I18: =VLOOKUP(E18,Cad.RateioConsumo!$B$4:$Q$77,11,FALSE) -> 0.0123 | J18: 01/2026 | K18: 46051 | L18: 46064 | M18: 205 | N18: 1.12834 | O18: =M18*N18 -> 231.3097 | Q18: =N18 -> 1.12834 | R18: =P18*Q18 -> 0 | S18: 2.85 | T18: 0.23 | U18: 0.005263 | V18: 0.024274 | W18: =ROUND(0.84318/((1-U18-V18)*(1-T18)),4) -> 1.1284 | AB18: =VLOOKUP(E18,Cad.RateioConsumo!$B$4:$Q$19,4,FALSE) -> 225.692.943-49 | AC18: =VLOOKUP(E18,Cad.RateioConsumo!$B$4:$U$19,20,FALSE) -> 24298
A19: ok | B19: =E19&J19 -> 2.402/2026 | C19: Usina 2 | D19: =VLOOKUP(C19,Cad.Usinas!$A$4:$B$6,2,FALSE) -> 3023594470 | E19: 2.4 | F19: =VLOOKUP(E19,Cad.RateioConsumo!$B$4:$Q$77,2,FALSE) -> Fernando Fonseca Diniz (Andre TVN) | G19: =VLOOKUP(E19,Cad.RateioConsumo!$B$4:$Q$77,5,FALSE) -> 3022544461 | H19: =VLOOKUP(E19,Cad.RateioConsumo!$B$4:$Q$77,7,FALSE) -> 241.125 | I19: =VLOOKUP(E19,Cad.RateioConsumo!$B$4:$Q$77,11,FALSE) -> 0.017223214 | J19: 02/2026 | K19: 46051 | L19: 46064 | M19: 269 | N19: 1.128364 | O19: =M19*N19 -> 303.52992 | Q19: =N19 -> 1.128364 | R19: =P19*Q19 -> 0 | S19: 3.85 | T19: 0.23 | U19: 0.005263 | V19: 0.024274 | W19: =ROUND(0.84318/((1-U19-V19)*(1-T19)),4) -> 1.1284 | AB19: =VLOOKUP(E19,Cad.RateioConsumo!$B$4:$Q$19,4,FALSE) -> 011.087.293-20 | AC19: =VLOOKUP(E19,Cad.RateioConsumo!$B$4:$U$19,20,FALSE) -> 31103
B20: =E20&J20 -> 2.002/2026 | C20: Usina 2 | D20: =VLOOKUP(C20,Cad.Usinas!$A$4:$B$6,2,FALSE) -> 3023594470 | E20: 2.0 | F20: =VLOOKUP(E20,Cad.RateioConsumo!$B$4:$Q$77,2,FALSE) -> Usina 2 | G20: =VLOOKUP(E20,Cad.RateioConsumo!$B$4:$Q$77,5,FALSE) -> 3023594470 | H20: =VLOOKUP(E20,Cad.RateioConsumo!$B$4:$Q$77,7,FALSE) -> 14000 | I20: =VLOOKUP(E20,Cad.RateioConsumo!$B$4:$Q$77,11,FALSE) -> 1 | J20: 02/2026 | O20: =M20*N20 -> 0 | Q20: =N20 -> 0 | R20: =P20*Q20 -> 0 | W20: =ROUND(0.84318/((1-U20-V20)*(1-T20)),4) -> 0.8432 | AB20: =VLOOKUP(E20,Cad.RateioConsumo!$B$4:$Q$19,4,FALSE) -> 61.434.675/0001-33 | AC20: =VLOOKUP(E20,Cad.RateioConsumo!$B$4:$U$19,20,FALSE) -> 0
A22: ok | B22: =E22&J22 -> 3.101/2026 | C22: Usina 3 | D22: =VLOOKUP(C22,Cad.Usinas!$A$4:$B$6,2,FALSE) -> 3023637013 | E22: 3.1 | F22: =VLOOKUP(E22,Cad.RateioConsumo!$B$4:$Q$77,2,FALSE) -> Associação dos Moradores do Residencial Araçagy | G22: =VLOOKUP(E22,Cad.RateioConsumo!$B$4:$Q$9,5,FALSE) -> 3021142432 | H22: =VLOOKUP(E22,Cad.RateioConsumo!$B$4:$Q$9,7,FALSE) -> 205.36364 | I22: =VLOOKUP(E22,Cad.RateioConsumo!$B$4:$Q$9,11,FALSE) -> 0.0147 | J22: 01/2026 | K22: 46026 | L22: 46046 | M22: 100 | N22: 1.1282 | O22: =M22*N22 -> 112.82 | P22: 114.86 | Q22: =N22 -> 1.1282 | R22: =P22*Q22 -> 129.58505 | S22: 2.19 | T22: 0.23 | U22: 0.005263 | V22: 0.024274 | W22: =ROUND(0.84318/((1-U22-V22)*(1-T22)),4) -> 1.1284 | AB22: =VLOOKUP(E22,Cad.RateioConsumo!$B$4:$Q$9,4,FALSE) -> 20.069.500/0001-97 | AC22: =VLOOKUP(E22,Cad.RateioConsumo!$B$4:$U$9,20,FALSE) -> 0
A23: ok | B23: =E23&J23 -> 3.201/2026 | C23: Usina 3 | D23: =VLOOKUP(C23,Cad.Usinas!$A$4:$B$6,2,FALSE) -> 3023637013 | E23: 3.2 | F23: =VLOOKUP(E23,Cad.RateioConsumo!$B$4:$Q$77,2,FALSE) -> Associação dos Moradores do Residencial Araçagy | G23: =VLOOKUP(E23,Cad.RateioConsumo!$B$4:$Q$9,5,FALSE) -> 3021149593 | H23: =VLOOKUP(E23,Cad.RateioConsumo!$B$4:$Q$9,7,FALSE) -> 734.33333 | I23: =VLOOKUP(E23,Cad.RateioConsumo!$B$4:$Q$9,11,FALSE) -> 0.0525 | J23: 01/2026 | K23: 46026 | L23: 46046 | M23: 30 | N23: 1.127667 | O23: =M23*N23 -> 33.83001 | P23: 660.25 | Q23: =N23 -> 1.127667 | R23: =P23*Q23 -> 744.54214 | S23: 0.65 | T23: 0.23 | U23: 0.005263 | V23: 0.024274 | W23: =ROUND(0.84318/ROUND(((1-U23-V23)*(1-T23)),4),4) -> 1.1283 | AB23: =VLOOKUP(E23,Cad.RateioConsumo!$B$4:$Q$9,4,FALSE) -> 20.069.500/0001-97 | AC23: =VLOOKUP(E23,Cad.RateioConsumo!$B$4:$U$9,20,FALSE) -> 0
A24: ok | B24: =E24&J24 -> 3.301/2026 | C24: Usina 3 | D24: =VLOOKUP(C24,Cad.Usinas!$A$4:$B$6,2,FALSE) -> 3023637013 | E24: 3.3 | F24: =VLOOKUP(E24,Cad.RateioConsumo!$B$4:$Q$77,2,FALSE) -> Associação dos Moradores do Residencial Araçagy | G24: =VLOOKUP(E24,Cad.RateioConsumo!$B$4:$Q$9,5,FALSE) -> 3021150559 | H24: =VLOOKUP(E24,Cad.RateioConsumo!$B$4:$Q$9,7,FALSE) -> 2086.4545 | I24: =VLOOKUP(E24,Cad.RateioConsumo!$B$4:$Q$9,11,FALSE) -> 0.107 | J24: 01/2026 | K24: 46026 | L24: 46046 | M24: 307.3 | N24: 1.128311 | O24: =M24*N24 -> 346.72997 | P24: 1528.95 | Q24: =N24 -> 1.128311 | R24: =P24*Q24 -> 1725.1311 | S24: 6.75 | T24: 0.23 | U24: 0.005263 | V24: 0.024274 | W24: =ROUND(0.84318/((1-U24-V24)*(1-T24)),4) -> 1.1284 | AB24: =VLOOKUP(E24,Cad.RateioConsumo!$B$4:$Q$9,4,FALSE) -> 20.069.500/0001-97 | AC24: =VLOOKUP(E24,Cad.RateioConsumo!$B$4:$U$9,20,FALSE) -> 0
A25: ok | B25: =E25&J25 -> 3.401/2026 | C25: Usina 3 | D25: =VLOOKUP(C25,Cad.Usinas!$A$4:$B$6,2,FALSE) -> 3023637013 | E25: 3.4 | F25: =VLOOKUP(E25,Cad.RateioConsumo!$B$4:$Q$77,2,FALSE) -> Antonio Jose Souza Filho | G25: =VLOOKUP(E25,Cad.RateioConsumo!$B$4:$Q$9,5,FALSE) -> 3007625048 | H25: =VLOOKUP(E25,Cad.RateioConsumo!$B$4:$Q$9,7,FALSE) -> 417.15385 | I25: =VLOOKUP(E25,Cad.RateioConsumo!$B$4:$Q$9,11,FALSE) -> 0.0298 | J25: 01/2026 | K25: 46029 | L25: 46046 | M25: 129.47 | N25: 1.128292 | O25: =M25*N25 -> 146.07997 | P25: 441.52 | Q25: =N25 -> 1.128292 | R25: =P25*Q25 -> 498.16348 | S25: 2.57 | T25: 0.23 | U25: 0.005263 | V25: 0.024274 | W25: =ROUND(0.84318/((1-U25-V25)*(1-T25)),4) -> 1.1284 | AB25: =VLOOKUP(E25,Cad.RateioConsumo!$B$4:$Q$9,4,FALSE) -> 682.957.583-49 | AC25: =VLOOKUP(E25,Cad.RateioConsumo!$B$4:$U$9,20,FALSE) -> 28283
A26: ok | B26: =E26&J26 -> 3.512/2025 | C26: Usina 3 | D26: =VLOOKUP(C26,Cad.Usinas!$A$4:$B$6,2,FALSE) -> 3023637013 | E26: 3.5 | F26: =VLOOKUP(E26,Cad.RateioConsumo!$B$4:$Q$77,2,FALSE) -> João Carlos Pereira Dutra Filho | G26: =VLOOKUP(E26,Cad.RateioConsumo!$B$4:$Q$9,5,FALSE) -> 1163310 | H26: =VLOOKUP(E26,Cad.RateioConsumo!$B$4:$Q$9,7,FALSE) -> 848.69231 | I26: =VLOOKUP(E26,Cad.RateioConsumo!$B$4:$Q$9,11,FALSE) -> 0.0606 | J26: 12/2025 | K26: 46021 | L26: 46028 | M26: 30 | N26: 1.42 | O26: =M26*N26 -> 42.6 | P26: 864 | Q26: =N26 -> 1.42 | R26: =P26*Q26 -> 1226.88 | S26: 0.83 | T26: 0.23 | U26: 0.007434 | V26: 0.034283 | W26: =ROUND(0.84318/((1-U26-V26)*(1-T26)),4) -> 1.1427 | AB26: =VLOOKUP(E26,Cad.RateioConsumo!$B$4:$Q$9,4,FALSE) -> 064837473-49 | AC26: =VLOOKUP(E26,Cad.RateioConsumo!$B$4:$U$9,20,FALSE) -> 19543
A27: ok | B27: =E27&J27 -> 3.601/2026 | C27: Usina 3 | D27: =VLOOKUP(C27,Cad.Usinas!$A$4:$B$6,2,FALSE) -> 3023637013 | E27: 3.6 | F27: =VLOOKUP(E27,Cad.RateioConsumo!$B$4:$Q$77,2,FALSE) -> Patricia Maria Abreu Machado | G27: =VLOOKUP(E27,Cad.RateioConsumo!$B$4:$Q$9,5,FALSE) -> 3006793931 | H27: =VLOOKUP(E27,Cad.RateioConsumo!$B$4:$Q$9,7,FALSE) -> 776.76923 | I27: =VLOOKUP(E27,Cad.RateioConsumo!$B$4:$Q$9,11,FALSE) -> 0.0555 | J27: 01/2026 | K27: 46034 | L27: 46048 | O27: =M27*N27 -> 0 | Q27: =N27 -> 0 | R27: =P27*Q27 -> 0 | W27: =ROUND(0.84318/((1-U27-V27)*(1-T27)),4) -> 0.8432 | X27: O contrato foi feito com base no consumo médio de 777 kwh e em dezembro foi consumido energia maior que a média por isso a energia paga pela Equatorial foi maior. Se existir uma tendência de aumento do consumo da energia favor nos informar para ajustarmos o contrato. | Y27: =W27-N27 -> 0.8432 | AB27: =VLOOKUP(E27,Cad.RateioConsumo!$B$4:$Q$9,4,FALSE) -> 676.211.553-53 | AC27: =VLOOKUP(E27,Cad.RateioConsumo!$B$4:$U$9,20,FALSE) -> 27174
A28: ok | B28: =E28&J28 -> 3.7 | C28: Usina 3 | D28: =VLOOKUP(C28,Cad.Usinas!$A$4:$B$6,2,FALSE) -> 3023637013 | E28: 3.7 | F28: =VLOOKUP(E28,Cad.RateioConsumo!$B$4:$Q$77,2,FALSE) -> Fatima Abdel Hafiz Khalifa Cavalcanti | G28: =VLOOKUP(E28,Cad.RateioConsumo!$B$4:$Q$22,5,FALSE) -> 38398091 | H28: =VLOOKUP(E28,Cad.RateioConsumo!$B$4:$Q$22,7,FALSE) -> 1013.3846 | I28: =VLOOKUP(E28,Cad.RateioConsumo!$B$4:$Q$22,11,FALSE) -> 0.0724 | O28: =M28*N28 -> 0 | Q28: =N28 -> 0 | R28: =P28*Q28 -> 0 | W28: =ROUND(0.84318/((1-U28-V28)*(1-T28)),4) -> 0.8432 | X28: =W28-Q28 -> 0.8432 | AB28: =VLOOKUP(E28,Cad.RateioConsumo!$B$4:$Q$19,4,FALSE) -> 840.670.553-15 | AC28: =VLOOKUP(E28,Cad.RateioConsumo!$B$4:$U$19,20,FALSE) -> 29085
B29: =E29&J29 -> 3.001/2026 | C29: Usina 3 | D29: =VLOOKUP(C29,Cad.Usinas!$A$4:$B$6,2,FALSE) -> 3023637013 | E29: 3.0 | F29: =VLOOKUP(E29,Cad.RateioConsumo!$B$4:$Q$77,2,FALSE) -> Usina 3 | G29: =VLOOKUP(E29,Cad.RateioConsumo!$B$4:$Q$77,5,FALSE) -> 3023637013 | H29: =VLOOKUP(E29,Cad.RateioConsumo!$B$4:$Q$77,7,FALSE) -> 8931.2331 | I29: =VLOOKUP(E29,Cad.RateioConsumo!$B$4:$Q$77,11,FALSE) -> 0.6799 | J29: 01/2026 | O29: =M29*N29 -> 0 | Q29: =N29 -> 0 | R29: =P29*Q29 -> 0 | W29: =ROUND(0.84318/((1-U29-V29)*(1-T29)),4) -> 0.8432 | AB29: =VLOOKUP(E29,Cad.RateioConsumo!$B$4:$Q$19,4,FALSE) -> 61.434.675/0001-33 | AC29: =VLOOKUP(E29,Cad.RateioConsumo!$B$4:$U$19,20,FALSE) -> 0
B30: =E30&J30 -> 1.001/2026 | C30: Usina 1 | D30: =VLOOKUP(C30,Cad.Usinas!$A$4:$B$6,2,FALSE) -> 3023633492 | E30: 1.0 | F30: =VLOOKUP(E30,Cad.RateioConsumo!$B$4:$Q$77,2,FALSE) -> Usina 1 | G30: =VLOOKUP(E30,Cad.RateioConsumo!$B$4:$Q$77,5,FALSE) -> 3023633492 | H30: =VLOOKUP(E30,Cad.RateioConsumo!$B$4:$Q$77,7,FALSE) -> 14000 | I30: =VLOOKUP(E30,Cad.RateioConsumo!$B$4:$Q$77,11,FALSE) -> 0.3201 | J30: 01/2026 | O30: =M30*N30 -> 0 | Q30: =N30 -> 0 | R30: =P30*Q30 -> 0 | W30: =ROUND(0.84318/((1-U30-V30)*(1-T30)),4) -> 0.8432 | Y30: A Equatorial cobrou errado uma tarida de GD2 , gerando itens que não são devidos: 1)Benefício Tarifário Bruto SCEE R$ 961,08 e 2) (-) Benefício Tarifário Líquido SCEE 702,62. O saldo deste valor foi dado como desconto para não te afetar os 15% de desconto na conta até que a Equatorial reverter esse valor. | AB30: =VLOOKUP(E30,Cad.RateioConsumo!$B$4:$Q$19,4,FALSE) -> #N/A | AC30: =VLOOKUP(E30,Cad.RateioConsumo!$B$4:$U$19,20,FALSE) -> #N/A
B31: =E31&J31 -> 2.101/2026 | C31: Usina 2 | D31: =VLOOKUP(C31,Cad.Usinas!$A$4:$B$6,2,FALSE) -> 3023594470 | E31: 2.1 | F31: =VLOOKUP(E31,Cad.RateioConsumo!$B$4:$Q$77,2,FALSE) -> Lucas Medeiros Lima | G31: =VLOOKUP(E31,Cad.RateioConsumo!$B$4:$Q$77,5,FALSE) -> 3002796782 | H31: =VLOOKUP(E31,Cad.RateioConsumo!$B$4:$Q$77,7,FALSE) -> 1536.5 | I31: =VLOOKUP(E31,Cad.RateioConsumo!$B$4:$Q$77,11,FALSE) -> 0.1098 | J31: 01/2026 | K31: 46034 | L31: 46048 | M31: 80 | O31: =M31*N31 -> 0 | P31: 499 | Q31: =N31 -> 0 | R31: =P31*Q31 -> 0 | W31: =ROUND(0.84318/((1-U31-V31)*(1-T31)),4) -> 0.8432 | X31: =108.62+211.48+79.91-164.51-59.72 -> 175.78 | Y31: A Equatorial errou no faturamento e cobrou indevidamente uma tarifa adicional:1)Benefício Tarifário Bruto SCEE e 2) (-) Benefício Tarifário Líquido SCEE . O saldo deste valor foi dado como desconto para não te afetar os 15% de desconto na conta até que a Equatorial reverter esse valor. | AB31: =VLOOKUP(E31,Cad.RateioConsumo!$B$4:$Q$19,4,FALSE) -> 612.634.903-28 | AC31: =VLOOKUP(E31,Cad.RateioConsumo!$B$4:$U$19,20,FALSE) -> 35943
A32: ok | B32: =E32&J32 -> 2.201/2026 | C32: Usina 2 | D32: =VLOOKUP(C32,Cad.Usinas!$A$4:$B$6,2,FALSE) -> 3023594470 | E32: 2.2 | F32: =VLOOKUP(E32,Cad.RateioConsumo!$B$4:$Q$77,2,FALSE) -> SORRISO SAUDE ODONTOLOGIA LTDA | G32: =VLOOKUP(E32,Cad.RateioConsumo!$B$4:$Q$77,5,FALSE) -> 3022893768 | H32: =VLOOKUP(E32,Cad.RateioConsumo!$B$4:$Q$77,7,FALSE) -> 859 | I32: =VLOOKUP(E32,Cad.RateioConsumo!$B$4:$Q$77,11,FALSE) -> 0.0614 | J32: 01/2026 | K32: 46030 | L32: 46037 | M32: 100 | N32: 1.1282 | O32: =M32*N32 -> 112.82 | P32: 399 | Q32: =N32 -> 1.1282 | R32: =P32*Q32 -> 450.1518 | S32: 1.85 | T32: 0.23 | U32: 0.005263 | V32: 0.024274 | W32: =ROUND(0.84318/((1-U32-V32)*(1-T32)),4) -> 1.1284 | AB32: =VLOOKUP(E32,Cad.RateioConsumo!$B$4:$Q$19,4,FALSE) -> 60.080.581/0001-40 | AC32: =VLOOKUP(E32,Cad.RateioConsumo!$B$4:$U$19,20,FALSE) -> 0
B33: =E33&J33 -> 2.001/2026 | C33: Usina 2 | D33: =VLOOKUP(C33,Cad.Usinas!$A$4:$B$6,2,FALSE) -> 3023594470 | E33: 2.0 | F33: =VLOOKUP(E33,Cad.RateioConsumo!$B$4:$Q$77,2,FALSE) -> Usina 2 | G33: =VLOOKUP(E33,Cad.RateioConsumo!$B$4:$Q$77,5,FALSE) -> 3023594470 | H33: =VLOOKUP(E33,Cad.RateioConsumo!$B$4:$Q$77,7,FALSE) -> 14000 | I33: =VLOOKUP(E33,Cad.RateioConsumo!$B$4:$Q$77,11,FALSE) -> 1 | J33: 01/2026 | O33: =M33*N33 -> 0 | Q33: =N33 -> 0 | R33: =P33*Q33 -> 0 | W33: =ROUND(0.84318/((1-U33-V33)*(1-T33)),4) -> 0.8432 | AB33: =VLOOKUP(E33,Cad.RateioConsumo!$B$4:$Q$19,4,FALSE) -> 61.434.675/0001-33 | AC33: =VLOOKUP(E33,Cad.RateioConsumo!$B$4:$U$19,20,FALSE) -> 0
A35: ok | B35: =E35&J35 -> 3.112/2025 | C35: Usina 3 | D35: =VLOOKUP(C35,Cad.Usinas!$A$4:$B$6,2,FALSE) -> 3023637013 | E35: 3.1 | F35: =VLOOKUP(E35,Cad.RateioConsumo!$B$4:$Q$77,2,FALSE) -> Associação dos Moradores do Residencial Araçagy | G35: =VLOOKUP(E35,Cad.RateioConsumo!$B$4:$Q$9,5,FALSE) -> 3021142432 | H35: =VLOOKUP(E35,Cad.RateioConsumo!$B$4:$Q$9,7,FALSE) -> 205.36364 | I35: =VLOOKUP(E35,Cad.RateioConsumo!$B$4:$Q$9,11,FALSE) -> 0.0147 | J35: 12/2025 | K35: 45995 | L35: 46015 | M35: 100 | N35: 1.142725 | O35: =M35*N35 -> 114.2725 | P35: 120.86 | Q35: =N35 -> 1.142725 | R35: =P35*Q35 -> 138.10974 | S35: 5.21 | T35: 0.23 | U35: 0.007434 | V35: 0.034283 | W35: =ROUND(0.84318/((1-U35-V35)*(1-T35)),4) -> 1.1427
A36: ok | B36: =E36&J36 -> 3.212/2025 | C36: Usina 3 | D36: =VLOOKUP(C36,Cad.Usinas!$A$4:$B$6,2,FALSE) -> 3023637013 | E36: 3.2 | F36: =VLOOKUP(E36,Cad.RateioConsumo!$B$4:$Q$77,2,FALSE) -> Associação dos Moradores do Residencial Araçagy | G36: =VLOOKUP(E36,Cad.RateioConsumo!$B$4:$Q$9,5,FALSE) -> 3021149593 | H36: =VLOOKUP(E36,Cad.RateioConsumo!$B$4:$Q$9,7,FALSE) -> 734.33333 | I36: =VLOOKUP(E36,Cad.RateioConsumo!$B$4:$Q$9,11,FALSE) -> 0.0525 | J36: 12/2025 | K36: 45995 | L36: 46015 | M36: 162.69 | N36: 1.142725 | O36: =M36*N36 -> 185.90993 | P36: 824.67 | Q36: =N36 -> 1.142725 | R36: =P36*Q36 -> 942.37103 | S36: 8.47 | T36: 0.23 | U36: 0.007434 | V36: 0.034283 | W36: =ROUND(0.84318/((1-U36-V36)*(1-T36)),4) -> 1.1427
A37: ok | B37: =E37&J37 -> 3.312/2025 | C37: Usina 3 | D37: =VLOOKUP(C37,Cad.Usinas!$A$4:$B$6,2,FALSE) -> 3023637013 | E37: 3.3 | F37: =VLOOKUP(E37,Cad.RateioConsumo!$B$4:$Q$77,2,FALSE) -> Associação dos Moradores do Residencial Araçagy | G37: =VLOOKUP(E37,Cad.RateioConsumo!$B$4:$Q$9,5,FALSE) -> 3021150559 | H37: =VLOOKUP(E37,Cad.RateioConsumo!$B$4:$Q$9,7,FALSE) -> 2086.4545 | I37: =VLOOKUP(E37,Cad.RateioConsumo!$B$4:$Q$9,11,FALSE) -> 0.107 | J37: 12/2025 | K37: 45995 | L37: 46015 | M37: 374.43 | N37: 1.142725 | O37: =M37*N37 -> 427.87052 | P37: 1682.32 | Q37: =N37 -> 1.142725 | R37: =P37*Q37 -> 1922.4291 | S37: 19.52 | T37: 0.23 | U37: 0.007434 | V37: 0.034283 | W37: =ROUND(0.84318/((1-U37-V37)*(1-T37)),4) -> 1.1427
A38: ok | B38: =E38&J38 -> 3.412/2025 | C38: Usina 3 | D38: =VLOOKUP(C38,Cad.Usinas!$A$4:$B$6,2,FALSE) -> 3023637013 | E38: 3.4 | F38: =VLOOKUP(E38,Cad.RateioConsumo!$B$4:$Q$77,2,FALSE) -> Antonio Jose Souza Filho | G38: =VLOOKUP(E38,Cad.RateioConsumo!$B$4:$Q$9,5,FALSE) -> 3007625048 | H38: =VLOOKUP(E38,Cad.RateioConsumo!$B$4:$Q$9,7,FALSE) -> 417.15385 | I38: =VLOOKUP(E38,Cad.RateioConsumo!$B$4:$Q$9,11,FALSE) -> 0.0298 | J38: 12/2025 | K38: 45996 | L38: 46015 | M38: 30 | N38: 1.142725 | O38: =M38*N38 -> 34.28175 | P38: 452 | Q38: =N38 -> 1.142725 | R38: =P38*Q38 -> 516.5117 | S38: 1.49 | T38: 0.23 | U38: 0.007434 | V38: 0.034283 | W38: =ROUND(0.84318/((1-U38-V38)*(1-T38)),4) -> 1.1427
A39: ok | B39: =E39&J39 -> 3.5 | C39: Usina 3 | D39: =VLOOKUP(C39,Cad.Usinas!$A$4:$B$6,2,FALSE) -> 3023637013 | E39: 3.5 | F39: =VLOOKUP(E39,Cad.RateioConsumo!$B$4:$Q$77,2,FALSE) -> João Carlos Pereira Dutra Filho | G39: =VLOOKUP(E39,Cad.RateioConsumo!$B$4:$Q$9,5,FALSE) -> 1163310 | H39: =VLOOKUP(E39,Cad.RateioConsumo!$B$4:$Q$9,7,FALSE) -> 848.69231 | I39: =VLOOKUP(E39,Cad.RateioConsumo!$B$4:$Q$9,11,FALSE) -> 0.0606 | O39: =M39*N39 -> 0 | Q39: =N39 -> 0 | R39: =P39*Q39 -> 0
A40: ok | B40: =E40&J40 -> 3.612/2025 | C40: Usina 3 | D40: =VLOOKUP(C40,Cad.Usinas!$A$4:$B$6,2,FALSE) -> 3023637013 | E40: 3.6 | F40: =VLOOKUP(E40,Cad.RateioConsumo!$B$4:$Q$77,2,FALSE) -> Patricia Maria Abreu Machado | G40: =VLOOKUP(E40,Cad.RateioConsumo!$B$4:$Q$9,5,FALSE) -> 3006793931 | H40: =VLOOKUP(E40,Cad.RateioConsumo!$B$4:$Q$9,7,FALSE) -> 776.76923 | I40: =VLOOKUP(E40,Cad.RateioConsumo!$B$4:$Q$9,11,FALSE) -> 0.0555 | J40: 12/2025 | K40: 46020 | L40: 46029 | M40: 210.2 | N40: 1.142626 | O40: =M40*N40 -> 240.17999 | P40: 871.79 | Q40: =N40 -> 1.142626 | R40: =P40*Q40 -> 996.12992 | S40: =4.87+1.18 -> 6.05 | T40: 0.23 | U40: 0.007434 | V40: 0.034283 | W40: =ROUND(0.84318/((1-U40-V40)*(1-T40)),4) -> 1.1427 | X40: O contrato foi feito com base no consumo médio de 777 kwh e em dezembro foi consumido energia maior que a média por isso a energia paga pela Equatorial foi maior. Se existir uma tendência de aumento do consumo da energia favor nos informar para ajustarmos o contrato. | Y40: =W40-N40 -> 7.4e-05
A41: ok | B41: =E41&J41 -> 3.712/2025 | C41: Usina 3 | D41: =VLOOKUP(C41,Cad.Usinas!$A$4:$B$6,2,FALSE) -> 3023637013 | E41: 3.7 | F41: =VLOOKUP(E41,Cad.RateioConsumo!$B$4:$Q$77,2,FALSE) -> Fatima Abdel Hafiz Khalifa Cavalcanti | G41: =VLOOKUP(E41,Cad.RateioConsumo!$B$4:$Q$22,5,FALSE) -> 38398091 | H41: =VLOOKUP(E41,Cad.RateioConsumo!$B$4:$Q$22,7,FALSE) -> 1013.3846 | I41: =VLOOKUP(E41,Cad.RateioConsumo!$B$4:$Q$22,11,FALSE) -> 0.0724 | J41: 12/2025 | K41: 46011 | L41: 45663 | M41: 30 | N41: 1.142 | O41: =M41*N41 -> 34.26 | P41: 1096 | Q41: =N41 -> 1.142 | R41: =P41*Q41 -> 1251.632 | S41: =0.48+0.64 -> 1.12 | T41: 0.23 | U41: 0.007434 | V41: 0.034283 | W41: =ROUND(0.84318/((1-U41-V41)*(1-T41)),4) -> 1.1427 | X41: =W41-Q41 -> 0.0007
B42: =E42&J42 -> 3.012/2025 | C42: Usina 3 | D42: =VLOOKUP(C42,Cad.Usinas!$A$4:$B$6,2,FALSE) -> 3023637013 | E42: 3.0 | F42: =VLOOKUP(E42,Cad.RateioConsumo!$B$4:$Q$77,2,FALSE) -> Usina 3 | G42: =VLOOKUP(E42,Cad.RateioConsumo!$B$4:$Q$77,5,FALSE) -> 3023637013 | H42: =VLOOKUP(E42,Cad.RateioConsumo!$B$4:$Q$77,7,FALSE) -> 8931.2331 | I42: =VLOOKUP(E42,Cad.RateioConsumo!$B$4:$Q$77,11,FALSE) -> 0.6799 | J42: 12/2025 | T42: 0.23 | U42: 0.007434 | V42: 0.034283 | W42: =ROUND(0.84318/((1-U42-V42)*(1-T42)),4) -> 1.1427
B43: =E43&J43 -> 1.012/2025 | C43: Usina 1 | D43: =VLOOKUP(C43,Cad.Usinas!$A$4:$B$6,2,FALSE) -> 3023633492 | E43: 1.0 | F43: =VLOOKUP(E43,Cad.RateioConsumo!$B$4:$Q$77,2,FALSE) -> Usina 1 | G43: =VLOOKUP(E43,Cad.RateioConsumo!$B$4:$Q$77,5,FALSE) -> 3023633492 | H43: =VLOOKUP(E43,Cad.RateioConsumo!$B$4:$Q$77,7,FALSE) -> 14000 | I43: =VLOOKUP(E43,Cad.RateioConsumo!$B$4:$Q$77,11,FALSE) -> 0.3201 | J43: 12/2025 | M43: 0 | T43: 0.23 | U43: 0.007434 | V43: 0.034283 | W43: =ROUND(0.84318/((1-U43-V43)*(1-T43)),4) -> 1.1427 | Y43: A Equatorial cobrou errado uma tarida de GD2 , gerando itens que não são devidos: 1)Benefício Tarifário Bruto SCEE R$ 961,08 e 2) (-) Benefício Tarifário Líquido SCEE 702,62. O saldo deste valor foi dado como desconto para não te afetar os 15% de desconto na conta até que a Equatorial reverter esse valor.
...

Sheet Medições
D1: Medição | E1: 1 | F1: 2 | G1: 3 | H1: 4 | I1: 5 | J1: 6 | K1: 7 | L1: 8 | M1: 9 | N1: 10 | O1: 11 | P1: 12 | Q1: 13 | R1: 14 | S1: 15 | T1: 16 | U1: 17 | V1: 18 | W1: 19 | X1: 20 | Y1: 21 | Z1: 22 | AA1: 23 | AB1: 24 | AC1: 25 | AD1: 26 | AE1: 27
Q2: C.Comopensado | R2: C.Comopensado | S2: Energia pela Equatorial | T2: Bandeira Tarifária | U2: Bandeira Tarifária | V2: Locação | W2: Economia | X2: Saldo de Geração | Y2: Saldo | Z2: Vencimento fatura | AA2: Economia Acumulada | AB2: Consumo Compensado Acumulado | AC2: Desconto | AD2: Ação | AG2: Desconto
B3: Consumo | C3: Geração | D3: Recibo | E3: Recibos | F3: Nome | G3: Conta Contrato | H3: Nome | I3: Consumidores | J3: Conta Contrato | K3: Referência Consumo | L3: Referência Geração | M3: Consumo Médio | N3: Percentual Rateio (%) | O3: Geração Proporcional | P3: Consumo | Q3: Consumo Compensado | R3: Tarifa | S3: Valor | T3: Tipo | U3: Valor | X3: Mês | Y3: Acumulado
B4: =H4&K4 -> 1.002/2026 | C4: =F4&L4 -> Usina 101/2026 | D4: =IF(J4=G4,0,1) -> 0 | E4: =IF(D4=0,"N/A",SUM($D4:D$83)) -> N/A | F4: Usina 1 | G4: =VLOOKUP(F4,Cad.Usinas!$A$4:$B$6,2,FALSE) -> 3023633492 | H4: 1.0 | I4: =VLOOKUP(H4,Cad.RateioConsumo!$B$4:$Z$106,2,FALSE) -> Usina 1 | J4: =VLOOKUP(H4,Cad.RateioConsumo!$B$4:$Z$106,5,FALSE) -> 3023633492 | K4: 02/2026 | L4: 01/2026 | M4: =VLOOKUP(H4,Cad.RateioConsumo!$B$4:$Z$106,7,FALSE) -> 14000 | N4: =ROUND(VLOOKUP(H4,Cad.RateioConsumo!$B$4:$Z$106,11,FALSE),4) -> 0.3201 | O4: =IFERROR(ROUND(VLOOKUP(C4,Hist.Geração!$A$4:$F$64,4,FALSE)*N4,2)," ") -> 3730.77 | P4: =IFERROR(VLOOKUP(B4,Hist.Consum!$B$5:$V$120,12,FALSE),"") -> 0 | Q4: =IFERROR(VLOOKUP(B4,Hist.Consum!$B$5:$V$120,15,FALSE),"") -> 0 | R4: =IFERROR(VLOOKUP(B4,Hist.Consum!$B$5:$W$120,22,FALSE),"") -> 0.8432 | S4: =IFERROR(Q4*R4,"") -> 0 | T4: =VLOOKUP(K4,Hist.BT!$A$4:$C$127,3,FALSE) -> Verde | U4: =IFERROR(ROUND(VLOOKUP(T4,Hist.BT!$G$3:$I$6,3,FALSE)*Q4,2),"") -> 0 | V4: =IFERROR(ROUND(SUM(S4+U4)*(1-AG4),2),"") -> 0 | W4: =S4+U4-V4 -> 0 | X4: =O4-Q4 -> 3730.77 | Y4: =SUMIF($J4:J$84,J4,$X4:X$84) -> 37788.77 | AB4: =SUMIF(J4:$J$84,J4,Q4:$Q$84) -> 0 | AC4: =IFERROR(VLOOKUP(B4,Hist.Consum!$B$5:$AD$120,23,FALSE),"") -> 0 | AE4: =IFERROR(VLOOKUP(B4,Hist.Consum!$B$5:$AD$120,24,FALSE),"") -> 0 | AG4: =VLOOKUP(H4,Cad.RateioConsumo!$B$4:$Z$106,8,FALSE) -> 0.15
B5: =H5&K5 -> 2.102/2026 | C5: =F5&L5 -> Usina 201/2026 | D5: =IF(J5=G5,0,1) -> 1 | E5: =IF(D5=0,"N/A",SUM($D5:D$83)) -> 49 | F5: Usina 2 | G5: =VLOOKUP(F5,Cad.Usinas!$A$4:$B$6,2,FALSE) -> 3023594470 | H5: 2.1 | I5: =VLOOKUP(H5,Cad.RateioConsumo!$B$4:$Z$106,2,FALSE) -> Lucas Medeiros Lima | J5: =VLOOKUP(H5,Cad.RateioConsumo!$B$4:$Z$106,5,FALSE) -> 3002796782 | K5: 02/2026 | L5: 01/2026 | M5: =VLOOKUP(H5,Cad.RateioConsumo!$B$4:$Z$106,7,FALSE) -> 1536.5 | N5: =ROUND(VLOOKUP(H5,Cad.RateioConsumo!$B$4:$Z$106,11,FALSE),4) -> 0.1098 | O5: =IFERROR(ROUND(VLOOKUP(C5,Hist.Geração!$A$4:$F$64,4,FALSE)*N5,2)," ") -> 1534.35 | P5: =IFERROR(VLOOKUP(B5,Hist.Consum!$B$5:$V$120,12,FALSE),"") -> 80 | Q5: =IFERROR(VLOOKUP(B5,Hist.Consum!$B$5:$V$120,15,FALSE),"") -> 499 | R5: =IFERROR(VLOOKUP(B5,Hist.Consum!$B$5:$W$120,22,FALSE),"") -> 0.8432 | S5: =IFERROR(Q5*R5,"") -> 420.7568 | T5: =VLOOKUP(K5,Hist.BT!$A$4:$C$127,3,FALSE) -> Verde | U5: =IFERROR(ROUND(VLOOKUP(T5,Hist.BT!$G$3:$I$6,3,FALSE)*Q5,2),"") -> 0 | V5: =IFERROR(ROUND(SUM(S5+U5)*(1-AG5),2),"") -> 357.64 | W5: =S5+U5-V5 -> 63.1168 | X5: =O5-Q5 -> 1035.35 | Y5: =SUMIF($J5:J$84,J5,$X5:X$84) -> #VALUE! | AC5: =IFERROR(VLOOKUP(B5,Hist.Consum!$B$5:$AD$120,23,FALSE),"") -> 175.78 | AD5: GD2 | AE5: =IFERROR(VLOOKUP(B5,Hist.Consum!$B$5:$AD$120,24,FALSE),"") -> A Equatorial errou no faturamento e cobrou indevidamente uma tarifa adicional:1)Benefício Tarifário Bruto SCEE e 2) (-) Benefício Tarifário Líquido SCEE . O saldo deste valor foi dado como desconto para não te afetar os 15% de desconto na conta até que a Equatorial reverter esse valor. | AG5: =VLOOKUP(H5,Cad.RateioConsumo!$B$4:$Z$106,8,FALSE) -> 0.15
B6: =H6&K6 -> 2.202/2026 | C6: =F6&L6 -> Usina 201/2026 | D6: =IF(J6=G6,0,1) -> 1 | E6: =IF(D6=0,"N/A",SUM($D6:D$83)) -> 48 | F6: Usina 2 | G6: =VLOOKUP(F6,Cad.Usinas!$A$4:$B$6,2,FALSE) -> 3023594470 | H6: 2.2 | I6: =VLOOKUP(H6,Cad.RateioConsumo!$B$4:$Z$106,2,FALSE) -> SORRISO SAUDE ODONTOLOGIA LTDA | J6: =VLOOKUP(H6,Cad.RateioConsumo!$B$4:$Z$106,5,FALSE) -> 3022893768 | K6: 02/2026 | L6: 01/2026 | M6: =VLOOKUP(H6,Cad.RateioConsumo!$B$4:$Z$106,7,FALSE) -> 859 | N6: =ROUND(VLOOKUP(H6,Cad.RateioConsumo!$B$4:$Z$106,11,FALSE),4) -> 0.0614 | O6: =IFERROR(ROUND(VLOOKUP(C6,Hist.Geração!$A$4:$F$64,4,FALSE)*N6,2)," ") -> 858 | P6: =IFERROR(VLOOKUP(B6,Hist.Consum!$B$5:$V$120,12,FALSE),"") | Q6: =IFERROR(VLOOKUP(B6,Hist.Consum!$B$5:$V$120,15,FALSE),"") | R6: =IFERROR(VLOOKUP(B6,Hist.Consum!$B$5:$W$120,22,FALSE),"") | S6: =IFERROR(Q6*R6,"") | T6: =VLOOKUP(K6,Hist.BT!$A$4:$C$127,3,FALSE) -> Verde | U6: =IFERROR(ROUND(VLOOKUP(T6,Hist.BT!$G$3:$I$6,3,FALSE)*Q6,2),"") | V6: =IFERROR(ROUND(SUM(S6+U6)*(1-AG6),2),"") | W6: =S6+U6-V6 -> #VALUE! | X6: =O6-Q6 -> #VALUE! | Y6: =SUMIF($J6:J$84,J6,$X6:X$84) -> #VALUE! | AC6: =IFERROR(VLOOKUP(B6,Hist.Consum!$B$5:$AD$120,23,FALSE),"") | AD6: GD2 | AE6: =IFERROR(VLOOKUP(B6,Hist.Consum!$B$5:$AD$120,24,FALSE),"") | AG6: =VLOOKUP(H6,Cad.RateioConsumo!$B$4:$Z$106,8,FALSE) -> 0.17
B7: =H7&K7 -> 2.302/2027 | C7: =F7&L7 -> Usina 201/2026 | D7: =IF(J7=G7,0,1) -> 1 | E7: =IF(D7=0,"N/A",SUM($D7:D$83)) -> 47 | F7: Usina 2 | G7: =VLOOKUP(F7,Cad.Usinas!$A$4:$B$6,2,FALSE) -> 3023594470 | H7: 2.3 | I7: =VLOOKUP(H7,Cad.RateioConsumo!$B$4:$Z$106,2,FALSE) -> José de Ribamar Aguiar Costa (Zeca) | J7: =VLOOKUP(H7,Cad.RateioConsumo!$B$4:$Z$106,5,FALSE) -> 3005806061 | K7: 02/2027 | L7: 01/2026 | M7: =VLOOKUP(H7,Cad.RateioConsumo!$B$4:$Z$106,7,FALSE) -> 172.38462 | N7: =ROUND(VLOOKUP(H7,Cad.RateioConsumo!$B$4:$Z$106,11,FALSE),4) -> 0.0123 | O7: =IFERROR(ROUND(VLOOKUP(C7,Hist.Geração!$A$4:$F$64,4,FALSE)*N7,2)," ") -> 171.88 | P7: =IFERROR(VLOOKUP(B7,Hist.Consum!$B$5:$V$120,12,FALSE),"") | Q7: =IFERROR(VLOOKUP(B7,Hist.Consum!$B$5:$V$120,15,FALSE),"") | R7: =IFERROR(VLOOKUP(B7,Hist.Consum!$B$5:$W$120,22,FALSE),"") | S7: =IFERROR(Q7*R7,"") | T7: =VLOOKUP(K7,Hist.BT!$A$4:$C$127,3,FALSE) -> #N/A | U7: =IFERROR(ROUND(VLOOKUP(T7,Hist.BT!$G$3:$I$6,3,FALSE)*Q7,2),"") | V7: =IFERROR(ROUND(SUM(S7+U7)*(1-AG7),2),"") | W7: =S7+U7-V7 -> #VALUE! | X7: =O7-Q7 -> #VALUE! | Y7: =SUMIF($J7:J$84,J7,$X7:X$84) -> #VALUE! | AC7: =IFERROR(VLOOKUP(B7,Hist.Consum!$B$5:$AD$120,23,FALSE),"") | AD7: GD3 | AE7: =IFERROR(VLOOKUP(B7,Hist.Consum!$B$5:$AD$120,24,FALSE),"") | AG7: =VLOOKUP(H7,Cad.RateioConsumo!$B$4:$Z$106,8,FALSE) -> 0.15
B8: =H8&K8 -> 2.402/2028 | C8: =F8&L8 -> Usina 201/2028 | D8: =IF(J8=G8,0,1) -> 1 | E8: =IF(D8=0,"N/A",SUM($D8:D$83)) -> 46 | F8: Usina 2 | G8: =VLOOKUP(F8,Cad.Usinas!$A$4:$B$6,2,FALSE) -> 3023594470 | H8: 2.4 | I8: =VLOOKUP(H8,Cad.RateioConsumo!$B$4:$Z$106,2,FALSE) -> Fernando Fonseca Diniz (Andre TVN) | J8: =VLOOKUP(H8,Cad.RateioConsumo!$B$4:$Z$106,5,FALSE) -> 3022544461 | K8: 02/2028 | L8: 01/2028 | M8: =VLOOKUP(H8,Cad.RateioConsumo!$B$4:$Z$106,7,FALSE) -> 241.125 | N8: =ROUND(VLOOKUP(H8,Cad.RateioConsumo!$B$4:$Z$106,11,FALSE),4) -> 0.0172 | O8: =IFERROR(ROUND(VLOOKUP(C8,Hist.Geração!$A$4:$F$64,4,FALSE)*N8,2)," ") | P8: =IFERROR(VLOOKUP(B8,Hist.Consum!$B$5:$V$120,12,FALSE),"") | Q8: =IFERROR(VLOOKUP(B8,Hist.Consum!$B$5:$V$120,15,FALSE),"") | R8: =IFERROR(VLOOKUP(B8,Hist.Consum!$B$5:$W$120,22,FALSE),"") | S8: =IFERROR(Q8*R8,"") | T8: =VLOOKUP(K8,Hist.BT!$A$4:$C$127,3,FALSE) -> #N/A | U8: =IFERROR(ROUND(VLOOKUP(T8,Hist.BT!$G$3:$I$6,3,FALSE)*Q8,2),"") | V8: =IFERROR(ROUND(SUM(S8+U8)*(1-AG8),2),"") | W8: =S8+U8-V8 -> #VALUE! | X8: =O8-Q8 -> #VALUE! | Y8: =SUMIF($J8:J$84,J8,$X8:X$84) -> #VALUE! | AC8: =IFERROR(VLOOKUP(B8,Hist.Consum!$B$5:$AD$120,23,FALSE),"") | AD8: GD4 | AE8: =IFERROR(VLOOKUP(B8,Hist.Consum!$B$5:$AD$120,24,FALSE),"") | AG8: =VLOOKUP(H8,Cad.RateioConsumo!$B$4:$Z$106,8,FALSE) -> 0.15
B9: =H9&K9 -> 2.002/2026 | C9: =F9&L9 -> Usina 201/2026 | D9: =IF(J9=G9,0,1) -> 0 | E9: =IF(D9=0,"N/A",SUM($D9:D$83)) -> N/A | F9: Usina 2 | G9: =VLOOKUP(F9,Cad.Usinas!$A$4:$B$6,2,FALSE) -> 3023594470 | H9: 2.0 | I9: =VLOOKUP(H9,Cad.RateioConsumo!$B$4:$Z$106,2,FALSE) -> Usina 2 | J9: =VLOOKUP(H9,Cad.RateioConsumo!$B$4:$Z$106,5,FALSE) -> 3023594470 | K9: 02/2026 | L9: 01/2026 | M9: =VLOOKUP(H9,Cad.RateioConsumo!$B$4:$Z$106,7,FALSE) -> 14000 | N9: =VLOOKUP(H9,Cad.RateioConsumo!$B$4:$Z$106,11,FALSE) -> 1 | O9: =IFERROR(ROUND(VLOOKUP(C9,Hist.Geração!$A$4:$F$64,4,FALSE)*N9,2)," ") -> 13974 | P9: =IFERROR(VLOOKUP(B9,Hist.Consum!$B$5:$V$120,12,FALSE),"") -> 0 | Q9: =IFERROR(VLOOKUP(B9,Hist.Consum!$B$5:$V$120,15,FALSE),"") -> 0 | R9: =IFERROR(VLOOKUP(B9,Hist.Consum!$B$5:$W$120,22,FALSE),"") -> 0.8432 | S9: =IFERROR(Q9*R9,"") -> 0 | T9: =VLOOKUP(K9,Hist.BT!$A$4:$C$127,3,FALSE) -> Verde | U9: =IFERROR(ROUND(VLOOKUP(T9,Hist.BT!$G$3:$I$6,3,FALSE)*Q9,2),"") -> 0 | V9: =IFERROR(ROUND(SUM(S9+U9)*(1-AG9),2),"") -> 0 | W9: =S9+U9-V9 -> 0 | X9: =O9-Q9 -> 13974 | Y9: =SUMIF($J9:J$84,J9,$X9:X$84) -> 125336 | AB9: =SUMIF($J9:J$84,J9,$Q9:Q$84) -> 0 | AC9: =IFERROR(VLOOKUP(B9,Hist.Consum!$B$5:$AD$120,23,FALSE),"") -> 0 | AG9: =VLOOKUP(H9,Cad.RateioConsumo!$B$4:$Z$106,8,FALSE) -> 0.15
B10: =H10&K10 -> 3.102/2026 | C10: =F10&L10 -> Usina 301/2026 | D10: =IF(J10=G10,0,1) -> 1 | E10: =IF(D10=0,"N/A",SUM($D10:D$83)) -> 45 | F10: Usina 3 | G10: =VLOOKUP(F10,Cad.Usinas!$A$4:$B$6,2,FALSE) -> 3023637013 | H10: 3.1 | I10: =VLOOKUP(H10,Cad.RateioConsumo!$B$4:$Z$106,2,FALSE) -> Associação dos Moradores do Residencial Araçagy | J10: =VLOOKUP(H10,Cad.RateioConsumo!$B$4:$Z$106,5,FALSE) -> 3021142432 | K10: 02/2026 | L10: 01/2026 | M10: =VLOOKUP(H10,Cad.RateioConsumo!$B$4:$Z$106,7,FALSE) -> 205.36364 | N10: =ROUND(VLOOKUP(H10,Cad.RateioConsumo!$B$4:$Z$106,11,FALSE),4) -> 0.0147 | O10: =IFERROR(ROUND(VLOOKUP(C10,Hist.Geração!$A$4:$F$64,4,FALSE)*N10,2)," ") -> 204.15 | P10: =IFERROR(VLOOKUP(B10,Hist.Consum!$B$5:$V$120,12,FALSE),"") -> 100 | Q10: =IFERROR(VLOOKUP(B10,Hist.Consum!$B$5:$V$120,15,FALSE),"") -> 108.87 | R10: =IFERROR(VLOOKUP(B10,Hist.Consum!$B$5:$W$120,22,FALSE),"") -> 1.1286 | S10: =IFERROR(Q10*R10,"") -> 122.87068 | T10: =VLOOKUP(K10,Hist.BT!$A$4:$C$127,3,FALSE) -> Verde | U10: =IFERROR(ROUND(VLOOKUP(T10,Hist.BT!$G$3:$I$6,3,FALSE)*Q10,2),"") -> 0 | V10: =IFERROR(ROUND(SUM(S10+U10)*(1-AG10),2),"") -> 104.44 | W10: =S10+U10-V10 -> 18.430682 | X10: =O10-Q10 -> 95.28 | Y10: =SUMIF($J10:J$84,J10,$X10:X$84) -> 366.59 | Z10: =Y10/M10 -> 1.7850775 | AB10: =SUMIF($J10:J$84,J10,$Q10:Q$84) -> 761.09 | AC10: =IFERROR(VLOOKUP(B10,Hist.Consum!$B$5:$AD$120,23,FALSE),"") -> 0 | AD10: Reduzir Percentual | AG10: =VLOOKUP(H10,Cad.RateioConsumo!$B$4:$Z$106,8,FALSE) -> 0.15
B11: =H11&K11 -> 3.202/2026 | C11: =F11&L11 -> Usina 301/2026 | D11: =IF(J11=G11,0,1) -> 1 | E11: =IF(D11=0,"N/A",SUM($D11:D$83)) -> 44 | F11: Usina 3 | G11: =VLOOKUP(F11,Cad.Usinas!$A$4:$B$6,2,FALSE) -> 3023637013 | H11: 3.2 | I11: =VLOOKUP(H11,Cad.RateioConsumo!$B$4:$Z$106,2,FALSE) -> Associação dos Moradores do Residencial Araçagy | J11: =VLOOKUP(H11,Cad.RateioConsumo!$B$4:$Z$106,5,FALSE) -> 3021149593 | K11: 02/2026 | L11: 01/2026 | M11: =VLOOKUP(H11,Cad.RateioConsumo!$B$4:$Z$106,7,FALSE) -> 734.33333 | N11: =ROUND(VLOOKUP(H11,Cad.RateioConsumo!$B$4:$Z$106,11,FALSE),4) -> 0.0525 | O11: =IFERROR(ROUND(VLOOKUP(C11,Hist.Geração!$A$4:$F$64,4,FALSE)*N11,2)," ") -> 729.12 | P11: =IFERROR(VLOOKUP(B11,Hist.Consum!$B$5:$V$120,12,FALSE),"") -> 219.41 | Q11: =IFERROR(VLOOKUP(B11,Hist.Consum!$B$5:$V$120,15,FALSE),"") -> 818.35 | R11: =IFERROR(VLOOKUP(B11,Hist.Consum!$B$5:$W$120,22,FALSE),"") -> 1.1286 | S11: =IFERROR(Q11*R11,"") -> 923.58981 | T11: =VLOOKUP(K11,Hist.BT!$A$4:$C$127,3,FALSE) -> Verde | U11: =IFERROR(ROUND(VLOOKUP(T11,Hist.BT!$G$3:$I$6,3,FALSE)*Q11,2),"") -> 0 | V11: =IFERROR(ROUND(SUM(S11+U11)*(1-AG11),2),"") -> 785.05 | W11: =S11+U11-V11 -> 138.53981 | X11: =O11-Q11 -> -89.23 | Y11: =SUMIF($J11:J$84,J11,$X11:X$84) -> 0.03 | AB11: =SUMIF($J11:J$84,J11,$Q11:Q$84) -> 4027.39 | AC11: =IFERROR(VLOOKUP(B11,Hist.Consum!$B$5:$AD$120,23,FALSE),"") -> 0 | AG11: =VLOOKUP(H11,Cad.RateioConsumo!$B$4:$Z$106,8,FALSE) -> 0.15
B12: =H12&K12 -> 3.302/2026 | C12: =F12&L12 -> Usina 301/2026 | D12: =IF(J12=G12,0,1) -> 1 | E12: =IF(D12=0,"N/A",SUM($D12:D$83)) -> 43 | F12: Usina 3 | G12: =VLOOKUP(F12,Cad.Usinas!$A$4:$B$6,2,FALSE) -> 3023637013 | H12: 3.3 | I12: =VLOOKUP(H12,Cad.RateioConsumo!$B$4:$Z$106,2,FALSE) -> Associação dos Moradores do Residencial Araçagy | J12: =VLOOKUP(H12,Cad.RateioConsumo!$B$4:$Z$106,5,FALSE) -> 3021150559 | K12: 02/2026 | L12: 01/2026 | M12: =VLOOKUP(H12,Cad.RateioConsumo!$B$4:$Z$106,7,FALSE) -> 2086.4545 | N12: =ROUND(VLOOKUP(H12,Cad.RateioConsumo!$B$4:$Z$106,11,FALSE),4) -> 0.107 | O12: =IFERROR(ROUND(VLOOKUP(C12,Hist.Geração!$A$4:$F$64,4,FALSE)*N12,2)," ") -> 1486.02 | P12: =IFERROR(VLOOKUP(B12,Hist.Consum!$B$5:$V$120,12,FALSE),"") -> 309.27 | Q12: =IFERROR(VLOOKUP(B12,Hist.Consum!$B$5:$V$120,15,FALSE),"") -> 1487.4 | R12: =IFERROR(VLOOKUP(B12,Hist.Consum!$B$5:$W$120,22,FALSE),"") -> 1.1286 | S12: =IFERROR(Q12*R12,"") -> 1678.6796 | T12: =VLOOKUP(K12,Hist.BT!$A$4:$C$127,3,FALSE) -> Verde | U12: =IFERROR(ROUND(VLOOKUP(T12,Hist.BT!$G$3:$I$6,3,FALSE)*Q12,2),"") -> 0 | V12: =IFERROR(ROUND(SUM(S12+U12)*(1-AG12),2),"") -> 1426.88 | W12: =S12+U12-V12 -> 251.79964 | X12: =O12-Q12 -> -1.38 | Y12: =SUMIF($J12:J$84,J12,$X12:X$84) -> -4.35 | AB12: =SUMIF($J12:J$84,J12,$Q12:Q$84) -> 9584.64 | AC12: =IFERROR(VLOOKUP(B12,Hist.Consum!$B$5:$AD$120,23,FALSE),"") -> 0 | AD12: Aumentar Percentual | AG12: =VLOOKUP(H12,Cad.RateioConsumo!$B$4:$Z$106,8,FALSE) -> 0.15
B13: =H13&K13 -> 3.402/2026 | C13: =F13&L13 -> Usina 301/2026 | D13: =IF(J13=G13,0,1) -> 1 | E13: =IF(D13=0,"N/A",SUM($D13:D$83)) -> 42 | F13: Usina 3 | G13: =VLOOKUP(F13,Cad.Usinas!$A$4:$B$6,2,FALSE) -> 3023637013 | H13: 3.4 | I13: =VLOOKUP(H13,Cad.RateioConsumo!$B$4:$Z$106,2,FALSE) -> Antonio Jose Souza Filho | J13: =VLOOKUP(H13,Cad.RateioConsumo!$B$4:$Z$106,5,FALSE) -> 3007625048 | K13: 02/2026 | L13: 01/2026 | M13: =VLOOKUP(H13,Cad.RateioConsumo!$B$4:$Z$106,7,FALSE) -> 417.15385 | N13: =ROUND(VLOOKUP(H13,Cad.RateioConsumo!$B$4:$Z$106,11,FALSE),4) -> 0.0298 | O13: =IFERROR(ROUND(VLOOKUP(C13,Hist.Geração!$A$4:$F$64,4,FALSE)*N13,2)," ") -> 413.86 | P13: =IFERROR(VLOOKUP(B13,Hist.Consum!$B$5:$V$120,12,FALSE),"") -> 79.13 | Q13: =IFERROR(VLOOKUP(B13,Hist.Consum!$B$5:$V$120,15,FALSE),"") -> 413.86 | R13: =IFERROR(VLOOKUP(B13,Hist.Consum!$B$5:$W$120,22,FALSE),"") -> 1.1286 | S13: =IFERROR(Q13*R13,"") -> 467.0824 | T13: =VLOOKUP(K13,Hist.BT!$A$4:$C$127,3,FALSE) -> Verde | U13: =IFERROR(ROUND(VLOOKUP(T13,Hist.BT!$G$3:$I$6,3,FALSE)*Q13,2),"") -> 0 | V13: =IFERROR(ROUND(SUM(S13+U13)*(1-AG13),2),"") -> 397.02 | W13: =S13+U13-V13 -> 70.062396 | X13: =O13-Q13 -> 0 | Y13: =SUMIF($J13:J$84,J13,$X13:X$84) -> 8.5265128e-14 | AB13: =SUMIF($J13:J$84,J13,$Q13:Q$84) -> 2286.03 | AC13: =IFERROR(VLOOKUP(B13,Hist.Consum!$B$5:$AD$120,23,FALSE),"") -> 0 | AG13: =VLOOKUP(H13,Cad.RateioConsumo!$B$4:$Z$106,8,FALSE) -> 0.15
B14: =H14&K14 -> 3.501/2026 | C14: =F14&L14 -> Usina 312/2025 | D14: =IF(J14=G14,0,1) -> 1 | E14: =IF(D14=0,"N/A",SUM($D14:D$83)) -> 41 | F14: Usina 3 | G14: =VLOOKUP(F14,Cad.Usinas!$A$4:$B$6,2,FALSE) -> 3023637013 | H14: 3.5 | I14: =VLOOKUP(H14,Cad.RateioConsumo!$B$4:$Z$106,2,FALSE) -> João Carlos Pereira Dutra Filho | J14: =VLOOKUP(H14,Cad.RateioConsumo!$B$4:$Z$106,5,FALSE) -> 1163310 | K14: 01/2026 | L14: 12/2025 | M14: =VLOOKUP(H14,Cad.RateioConsumo!$B$4:$Z$106,7,FALSE) -> 848.69231 | N14: =ROUND(VLOOKUP(H14,Cad.RateioConsumo!$B$4:$Z$106,11,FALSE),4) -> 0.0606 | O14: =IFERROR(ROUND(VLOOKUP(C14,Hist.Geração!$A$4:$F$64,4,FALSE)*N14,2)," ") -> 865.13 | P14: =IFERROR(VLOOKUP(B14,Hist.Consum!$B$5:$V$120,12,FALSE),"") -> 30 | Q14: =IFERROR(VLOOKUP(B14,Hist.Consum!$B$5:$V$120,15,FALSE),"") -> 937 | R14: =IFERROR(VLOOKUP(B14,Hist.Consum!$B$5:$W$120,22,FALSE),"") -> 1.1286 | S14: =IFERROR(Q14*R14,"") -> 1057.4982 | T14: =VLOOKUP(K14,Hist.BT!$A$4:$C$127,3,FALSE) -> Verde | U14: =IFERROR(ROUND(VLOOKUP(T14,Hist.BT!$G$3:$I$6,3,FALSE)*Q14,2),"") -> 0 | V14: =IFERROR(ROUND(SUM(S14+U14)*(1-AG14),2),"") -> 898.87 | W14: =S14+U14-V14 -> 158.6282 | X14: =O14-Q14 -> -71.87 | Y14: =SUMIF(J4:$J$84,J14,X4:$X$84) -> 16.04 | AB14: =SUMIF(J4:$J$84,J14,Q4:$Q$84) -> 1811.52 | AC14: =IFERROR(VLOOKUP(B14,Hist.Consum!$B$5:$AD$120,23,FALSE),"") -> 0 | AD14: =IF((Y14/M14)>1,"Mudar Urgente",IF((Y14/M14)>0.4,"Rever Rateio",("ok"))) -> ok | AG14: =VLOOKUP(H14,Cad.RateioConsumo!$B$4:$Z$106,8,FALSE) -> 0.15
